Workbook

Sheet Допущения
A1: Допущения модели. Меняйте значения в колонках C–E (жёлтые): все листы пересчитаются. ФАКТ = есть источник, ОЦЕНКА = допущение аналитика.
A2: id | B2: Допущение | C2: Осторожный | D2: Базовый | E2: Оптимистичный | F2: Ед. | G2: Источник / тип | H2: Уверенность
B3: ОБЩИЕ: КОММЕРЦИЯ НА OZON
A4: aov | B4: Средний чек заказа на Ozon (детские вещи) | C4: 1300 | D4: 1600 | E4: 2000 | F4: ₽ | G4: Владелец (1 600 ₽). Края диапазона: оценка | H4: средняя
A5: ds_margin | B5: Чистая маржа дропшиппинга FBS на заказ (после комиссии, логистики, возвратов, налога) | C5: 0.08 | D5: 0.12 | E5: 0.18 | F5: % от чека | G5: ОЦЕНКА. Комиссии Ozon 2026 на одежду и детские товары 43–55% (Коммерсантъ 8401352, RB.ru, Selsup). Прежний анализ брал 15%. Нужна выгрузка владельца | H5: низкая
A6: cr_ozon | B6: Конверсия внешнего клика в заказ на Ozon | C6: 0.02 | D6: 0.035 | E6: 0.05 | F6: % | G6: ОЦЕНКА: публичной статистики нет. Прежний анализ брал 5% | H6: низкая
A7: ozon_mult | B7: «Эффект Ozon»: множитель к заказам от внешнего трафика (органика) | C7: 1 | D7: 1.15 | E7: 1.5 | F7: x | G7: ОЦЕНКА: Ozon официально не подтверждает влияние внешнего трафика на ранжирование | H7: низкая
A8: rpm | B8: Доход РСЯ на 1 000 визитов сайта | C8: 40 | D8: 80 | E8: 150 | F8: ₽ | G8: Нет данных по нише; Habr: десятки центов за 1 000 показов. ОЦЕНКА | H8: низкая
A9: tg_cps | B9: Стоимость платного подписчика Telegram (посевы, ниша дети и родители) | C9: 300 | D9: 180 | E9: 100 | F9: ₽ | G9: Обзор по тематикам: «дети и родители» 120–600 ₽ (нативные посевы); TG Ads, детская психология: 32–105 ₽ (Habr) | H9: средняя
A10: tg_cpm | B10: CPM рекламного поста в своём канале | C10: 300 | D10: 500 | E10: 700 | F10: ₽ | G10: ОЦЕНКА. Канал 50k: 3–10 тыс. ₽ за пост (Точка, Tele-scope); мем-каналы CPM 150–200, IT 1 000–2 000 | H10: средняя
A11: tg_view | B11: Доля подписчиков, видящих пост | C11: 0.22 | D11: 0.28 | E11: 0.35 | F11: % | G11: ОЦЕНКА (типичный ERR для каналов 10–60k) | H11: средняя
A12: tg_ads_pm | B12: Рекламных постов в месяц в своём канале | C12: 4 | D12: 8 | E12: 12 | F12: шт | G12: ОЦЕНКА; больше постов снижают охват | H12: средняя
A13: tg_org | B13: Доля подписчиков, пришедших бесплатно (из клипов, SEO) | C13: 0.2 | D13: 0.4 | E13: 0.6 | F13: % | G13: ОЦЕНКА | H13: низкая
A14: tax_serv | B14: Налог с выручки услуг/обучения (УСН доходы) | C14: 0.06 | D14: 0.06 | E14: 0.06 | F14: % | G14: ОЦЕНКА; режим уточнить у владельца | H14: средняя
B15: КОНТЕНТ-ЯДРО
A16: core_full | B16: Полный эскалатор: команда и гонорары в месяц | C16: 480000 | D16: 420000 | E16: 360000 | F16: ₽/мес | G16: ОЦЕНКА: продюсер-редактор, монтаж, SEO-автор, SMM, гонорары профессорам и рецензентам. Прежний анализ: 300–500 тыс. | H16: средняя
A17: core_lite | B17: Урезанное ядро (без подкастов и сетки блогов) | C17: 220000 | D17: 180000 | E17: 150000 | F17: ₽/мес | G17: ОЦЕНКА: 1 редактор-продюсер, монтаж на сдельной, рецензент | H17: средняя
A18: capex_full | B18: Старт полного эскалатора (сайт, дизайн, техника) | C18: 600000 | D18: 400000 | E18: 300000 | F18: ₽ | G18: ОЦЕНКА; свой продакшн снижает | H18: средняя
A19: capex_lite | B19: Старт урезанного ядра | C19: 250000 | D19: 150000 | E19: 100000 | F19: ₽ | G19: ОЦЕНКА | H19: средняя
B20: A. ПОЛНЫЙ ЭСКАЛАТОР → ДРОПШИППИНГ OZON
A21: A_visits | B21: Визиты сайта в месяц на 36-м месяце | C21: 60000 | D21: 150000 | E21: 400000 | F21: визитов | G21: Прежний анализ 60/200/500 тыс.; база снижена из-за нейроответов (инфо-сайты −30%, Kokoc через ppc.world; −15…−60%, Timeweb) | H21: низкая
A22: A_subs | B22: Подписчики Telegram на 36-м месяце | C22: 10000 | D22: 25000 | E22: 60000 | F22: подп. | G22: Прежний 15/40/100 тыс. снижен: каждый подписчик стоит денег (см. tg_cps) | H22: низкая
A23: A_clips | B23: Просмотры клипов в месяц на 36-м месяце | C23: 2000000 | D23: 6000000 | E23: 15000000 | F23: просм. | G23: Прежний анализ; ОЦЕНКА | H23: низкая
A24: A_ctr_site | B24: Доля визитов медстатей с кликом на Ozon | C24: 0.005 | D24: 0.012 | E24: 0.025 | F24: % | G24: ОЦЕНКА: информационный медицинский интент, товар не в фокусе | H24: низкая
A25: A_click_sub | B25: Кликов на Ozon на подписчика в месяц | C25: 0.15 | D25: 0.3 | E25: 0.6 | F25: клик | G25: ОЦЕНКА | H25: низкая
A26: A_ctr_clip | B26: Кликов на Ozon на 1 просмотр клипа | C26: 0.0001 | D26: 0.0003 | E26: 0.0005 | F26: % | G26: ОЦЕНКА: клипы VK/Rutube дают мало переходов | H26: низкая
A27: A_start | B27: Месяц начала трафика | C27: 3 | D27: 3 | E27: 2 | F27: мес | G27: ОЦЕНКА | H27: средняя
A28: A_k | B28: Форма кривой роста (>1 медленный старт) | C28: 1.5 | D28: 1.3 | E28: 1.1 | G28: ОЦЕНКА | H28: средняя
B29: D. ПЛАТНЫЕ КУРСЫ И КЛУБ ДЛЯ РОДИТЕЛЕЙ (поверх A)
A30: D_start | B30: Месяц первого запуска | C30: 12 | D30: 9 | E30: 7 | F30: мес | G30: ОЦЕНКА | H30: средняя
A31: D_price | B31: Цена курса | C31: 1900 | D31: 2900 | E31: 3900 | F31: ₽ | G31: ОЦЕНКА; на рынке много бесплатного (Stepik, бесплатные курсы первой помощи) | H31: низкая
A32: D_launch | B32: Запусков курса в год | C32: 2 | D32: 3 | E32: 4 | F32: шт | G32: ОЦЕНКА | H32: средняя
A33: D_conv | B33: Конверсия тёплой аудитории в покупку за запуск | C33: 0.004 | D33: 0.01 | E33: 0.018 | F33: % | G33: ОЦЕНКА (инфобиз: 0,5–2% от базы) | H33: низкая
A34: D_warm | B34: Доп. тёплая база (email, VK) к подписчикам TG | C34: 0.5 | D34: 0.8 | E34: 1 | F34: x | G34: ОЦЕНКА | H34: низкая
A35: D_club_price | B35: Подписка клуба | C35: 290 | D35: 390 | E35: 490 | F35: ₽/мес | G35: ОЦЕНКА | H35: средняя
A36: D_club_pen | B36: Доля тёплой базы в клубе | C36: 0.003 | D36: 0.008 | E36: 0.015 | F36: % | G36: ОЦЕНКА | H36: низкая
A37: D_fees | B37: Платформа и эквайринг | C37: 0.12 | D37: 0.1 | E37: 0.08 | F37: % выручки | G37: ОЦЕНКА | H37: средняя
A38: D_mkt | B38: Реклама запусков | C38: 0.25 | D38: 0.2 | E38: 0.15 | F38: % выручки курса | G38: ОЦЕНКА | H38: низкая
A39: D_team | B39: Куратор и поддержка | C39: 120000 | D39: 100000 | E39: 80000 | F39: ₽/мес | G39: ОЦЕНКА | H39: средняя
A40: D_capex | B40: Производство 2 курсов | C40: 1200000 | D40: 800000 | E40: 600000 | F40: ₽ | G40: ОЦЕНКА | H40: средняя
...

Sheet Сводка
A1: Сводка по моделям и сценариям (₽). Пересчитывается из листов моделей. 99 = не достигнуто за 36 мес.
A2: Модель | B2: Сценарий | C2: Выручка год 1 | D2: Выручка год 2 | E2: Выручка год 3 | F2: Опер. прибыль год 3 | G2: Опер. прибыль, мес. 36 | H2: Макс. глубина минуса | I2: Накоплено за 36 мес | J2: Мес. устойчивой опер. прибыли | K2: Мес. окупаемости | L2: CAPEX+оборотка 36 мес
A3: A. Эскалатор → дропшиппинг | B3: Осторожный | C3: =A_дропшиппинг!AM10 -> 37421.799 | D3: =A_дропшиппинг!AN10 -> 214436.15 | E3: =A_дропшиппинг!AO10 -> 481526.54 | F3: =A_дропшиппинг!AO17 -> -6847586.6 | G3: =A_дропшиппинг!AL17 -> -576058.35 | H3: =MIN(0,MIN(A_дропшиппинг!C20:AL20)) -> -20184999 | I3: =A_дропшиппинг!AL20 -> -20184999 | J3: =MIN(A_дропшиппинг!C21:AL21) -> 99 | K3: =MIN(A_дропшиппинг!C22:AL22) -> 99 | L3: =A_дропшиппинг!AP18 -> 600000
A4: A. Эскалатор → дропшиппинг | B4: Базовый | C4: =A_дропшиппинг!AM30 -> 707307.05 | D4: =A_дропшиппинг!AN30 -> 3380003.3 | E4: =A_дропшиппинг!AO30 -> 6839270.1 | F4: =A_дропшиппинг!AO37 -> -5019487.7 | G4: =A_дропшиппинг!AL37 -> -398675.88 | H4: =MIN(0,MIN(A_дропшиппинг!C40:AL40)) -> -16396795 | I4: =A_дропшиппинг!AL40 -> -16396795 | J4: =MIN(A_дропшиппинг!C41:AL41) -> 99 | K4: =MIN(A_дропшиппинг!C42:AL42) -> 99 | L4: =A_дропшиппинг!AP38 -> 400000
A5: A. Эскалатор → дропшиппинг | B5: Оптимистичный | C5: =A_дропшиппинг!AM50 -> 12898301 | D5: =A_дропшиппинг!AN50 -> 45022667 | E5: =A_дропшиппинг!AO50 -> 79851626 | F5: =A_дропшиппинг!AO57 -> 11412540 | G5: =A_дропшиппинг!AL57 -> 1234996.1 | H5: =MIN(0,MIN(A_дропшиппинг!C60:AL60)) -> -2728050.9 | I5: =A_дропшиппинг!AL60 -> 12935721 | J5: =MIN(A_дропшиппинг!C61:AL61) -> 12 | K5: =MIN(A_дропшиппинг!C62:AL62) -> 22 | L5: =A_дропшиппинг!AP58 -> 300000
A6: D. Эскалатор + курсы/клуб (A+D) | B6: Осторожный | C6: =D_курсы_родителям!AM9 -> 5112.2215 | D6: =D_курсы_родителям!AN9 -> 132166.9 | E6: =D_курсы_родителям!AO9 -> 296787.03 | F6: =D_курсы_родителям!AO13 -> -8088206.8 | G6: =D_курсы_родителям!AL13 -> -674527.35 | H6: =MIN(0,MIN(D_курсы_родителям!C16:AL16)) -> -24213396 | I6: =D_курсы_родителям!AL16 -> -24213396 | J6: =MIN(D_курсы_родителям!C17:AL17) -> 99 | K6: =MIN(D_курсы_родителям!C18:AL18) -> 99 | L6: =D_курсы_родителям!AP14 -> 1800000
A7: D. Эскалатор + курсы/клуб (A+D) | B7: Базовый | C7: =D_курсы_родителям!AM25 -> 308915.81 | D7: =D_курсы_родителям!AN25 -> 2206477.7 | E7: =D_курсы_родителям!AO25 -> 4464699 | F7: =D_курсы_родителям!AO29 -> -3093423.5 | G7: =D_курсы_родителям!AL29 -> -171939.88 | H7: =MIN(0,MIN(D_курсы_родителям!C32:AL32)) -> -15209519 | I7: =D_курсы_родителям!AL32 -> -15209519 | J7: =MIN(D_курсы_родителям!C33:AL33) -> 99 | K7: =MIN(D_курсы_родителям!C34:AL34) -> 99 | L7: =D_курсы_родителям!AP30 -> 1200000
A8: D. Эскалатор + курсы/клуб (A+D) | B8: Оптимистичный | C8: =D_курсы_родителям!AM41 -> 4677746.3 | D8: =D_курсы_родителям!AN41 -> 20702011 | E8: =D_курсы_родителям!AO41 -> 36716823 | F8: =D_курсы_родителям!AO45 -> 37837916 | G8: =D_курсы_родителям!AL45 -> 3907196.1 | H8: =MIN(0,MIN(D_курсы_родителям!C48:AL48)) -> -2911327.5 | I8: =D_курсы_родителям!AL48 -> 56170683 | J8: =MIN(D_курсы_родителям!C49:AL49) -> 7 | K8: =MIN(D_курсы_родителям!C50:AL50) -> 13 | L8: =D_курсы_родителям!AP46 -> 900000
A9: B. Свой бренд текстиля | B9: Осторожный | C9: =B_свой_бренд!AM6 -> 800910.83 | D9: =B_свой_бренд!AN6 -> 4766768.5 | E9: =B_свой_бренд!AO6 -> 9780998.6 | F9: =B_свой_бренд!AO13 -> -4299473.4 | G9: =B_свой_бренд!AL13 -> -383000 | H9: =MIN(0,MIN(B_свой_бренд!C16:AL16)) -> -12728870 | I9: =B_свой_бренд!AL16 -> -12728870 | J9: =MIN(B_свой_бренд!C17:AL17) -> 99 | K9: =MIN(B_свой_бренд!C18:AL18) -> 99 | L9: =B_свой_бренд!AP14 -> 1518000
A10: B. Свой бренд текстиля | B10: Базовый | C10: =B_свой_бренд!AM22 -> 6995454.5 | D10: =B_свой_бренд!AN22 -> 28914545 | E10: =B_свой_бренд!AO22 -> 51300000 | F10: =B_свой_бренд!AO29 -> -75000 | G10: =B_свой_бренд!AL29 -> 36500 | H10: =MIN(0,MIN(B_свой_бренд!C32:AL32)) -> -7294000 | I10: =B_свой_бренд!AL32 -> -7294000 | J10: =MIN(B_свой_бренд!C33:AL33) -> 32 | K10: =MIN(B_свой_бренд!C34:AL34) -> 99 | L10: =B_свой_бренд!AP30 -> 3734500
A11: B. Свой бренд текстиля | B11: Оптимистичный | C11: =B_свой_бренд!AM38 -> 33685821 | D11: =B_свой_бренд!AN38 -> 1.0995849e+08 | E11: =B_свой_бренд!AO38 -> 1.8006735e+08 | F11: =B_свой_бренд!AO45 -> 36718179 | G11: =B_свой_бренд!AL45 -> 3620000 | H11: =MIN(0,MIN(B_свой_бренд!C48:AL48)) -> -1227454.5 | I11: =B_свой_бренд!AL48 -> 55016291 | J11: =MIN(B_свой_бренд!C49:AL49) -> 4 | K11: =MIN(B_свой_бренд!C50:AL50) -> 10 | L11: =B_свой_бренд!AP46 -> 8396000
A12: C. Обучение профи (НГУ) | B12: Осторожный | C12: =C_обучение_профи!AM8 -> 14357.571 | D12: =C_обучение_профи!AN8 -> 432418.7 | E12: =C_обучение_профи!AO8 -> 1224331 | F12: =C_обучение_профи!AO12 -> -2473459.9 | G12: =C_обучение_профи!AL12 -> -208190 | H12: =MIN(0,MIN(C_обучение_профи!C15:AL15)) -> -8600266.4 | I12: =C_обучение_профи!AL15 -> -8600266.4 | J12: =MIN(C_обучение_профи!C16:AL16) -> 99 | K12: =MIN(C_обучение_профи!C17:AL17) -> 99 | L12: =C_обучение_профи!AP13 -> 1500000
A13: C. Обучение профи (НГУ) | B13: Базовый | C13: =C_обучение_профи!AM23 -> 380135.78 | D13: =C_обучение_профи!AN23 -> 3431133.7 | E13: =C_обучение_профи!AO23 -> 7641135.8 | F13: =C_обучение_профи!AO27 -> 1322099.8 | G13: =C_обучение_профи!AL27 -> 186400 | H13: =MIN(0,MIN(C_обучение_профи!C30:AL30)) -> -3266386.5 | I13: =C_обучение_профи!AL30 -> -1910941.7 | J13: =MIN(C_обучение_профи!C31:AL31) -> 23 | K13: =MIN(C_обучение_профи!C32:AL32) -> 99 | L13: =C_обучение_профи!AP28 -> 1000000
A14: C. Обучение профи (НГУ) | B14: Оптимистичный | C14: =C_обучение_профи!AM38 -> 3645000 | D14: =C_обучение_профи!AN38 -> 17617500 | E14: =C_обучение_профи!AO38 -> 32197500 | F14: =C_обучение_профи!AO42 -> 20416275 | G14: =C_обучение_профи!AL42 -> 2085600 | H14: =MIN(0,MIN(C_обучение_профи!C45:AL45)) -> -1240412.5 | I14: =C_обучение_профи!AL45 -> 30937400 | J14: =MIN(C_обучение_профи!C46:AL46) -> 7 | K14: =MIN(C_обучение_профи!C47:AL47) -> 12 | L14: =C_обучение_профи!AP43 -> 700000
A15: E. B2B: лицензия + продакшн | B15: Осторожный | C15: =E_B2B!AM7 -> 900000 | D15: =E_B2B!AN7 -> 1350000 | E15: =E_B2B!AO7 -> 1800000 | F15: =E_B2B!AO11 -> -3348000 | G15: =E_B2B!AL11 -> -279000 | H15: =MIN(0,MIN(E_B2B!C14:AL14)) -> -11423000 | I15: =E_B2B!AL14 -> -11423000 | J15: =MIN(E_B2B!C15:AL15) -> 99 | K15: =MIN(E_B2B!C16:AL16) -> 99 | L15: =E_B2B!AP12 -> 450000
A16: E. B2B: лицензия + продакшн | B16: Базовый | C16: =E_B2B!AM21 -> 1700000 | D16: =E_B2B!AN21 -> 4150000 | E16: =E_B2B!AO21 -> 6600000 | F16: =E_B2B!AO25 -> 564000 | G16: =E_B2B!AL25 -> 94000 | H16: =MIN(0,MIN(E_B2B!C28:AL28)) -> -4081000 | I16: =E_B2B!AL28 -> -3517000 | J16: =MIN(E_B2B!C29:AL29) -> 31 | K16: =MIN(E_B2B!C30:AL30) -> 99 | L16: =E_B2B!AP26 -> 300000
A17: E. B2B: лицензия + продакшн | B17: Оптимистичный | C17: =E_B2B!AM35 -> 3966666.7 | D17: =E_B2B!AN35 -> 11500000 | E17: =E_B2B!AO35 -> 19000000 | F17: =E_B2B!AO39 -> 10030000 | G17: =E_B2B!AL39 -> 1012000 | H17: =MIN(0,MIN(E_B2B!C42:AL42)) -> -1176000 | I17: =E_B2B!AL42 -> 13858667 | J17: =MIN(E_B2B!C43:AL43) -> 10 | K17: =MIN(E_B2B!C44:AL44) -> 16 | L17: =E_B2B!AP40 -> 200000
A18: F. Минимум: подборки + TG | B18: Осторожный | C18: =F_минимум!AM9 -> 158854 | D18: =F_минимум!AN9 -> 663934.09 | E18: =F_минимум!AO9 -> 1302563.9 | F18: =F_минимум!AO13 -> -1849963.1 | G18: =F_минимум!AL13 -> -153687.3 | H18: =MIN(0,MIN(F_минимум!C16:AL16)) -> -5604251.8 | I18: =F_минимум!AL16 -> -5604251.8 | J18: =MIN(F_минимум!C17:AL17) -> 99 | K18: =MIN(F_минимум!C18:AL18) -> 99 | L18: =F_минимум!AP14 -> 150000
A19: F. Минимум: подборки + TG | B19: Базовый | C19: =F_минимум!AM25 -> 1909703.8 | D19: =F_минимум!AN25 -> 7300042 | E19: =F_минимум!AO25 -> 13618861 | F19: =F_минимум!AO29 -> -237169.07 | G19: =F_минимум!AL29 -> 10034.058 | H19: =MIN(0,MIN(F_минимум!C32:AL32)) -> -2768294.1 | I19: =F_минимум!AL32 -> -2753793.5 | J19: =MIN(F_минимум!C33:AL33) -> 35 | K19: =MIN(F_минимум!C34:AL34) -> 99 | L19: =F_минимум!AP30 -> 100000
A20: F. Минимум: подборки + TG | B20: Оптимистичный | C20: =F_минимум!AM41 -> 23081143 | D20: =F_минимум!AN41 -> 73440000 | E20: =F_минимум!AO41 -> 1.2379886e+08 | F20: =F_минимум!AO45 -> 20768709 | G20: =F_минимум!AL45 -> 2079771.4 | H20: =MIN(0,MIN(F_минимум!C48:AL48)) -> -252468.57 | I20: =F_минимум!AL48 -> 34871600 | J20: =MIN(F_минимум!C49:AL49) -> 4 | K20: =MIN(F_минимум!C50:AL50) -> 6 | L20: =F_минимум!AP46 -> 70000
A21: R. Комбо: ядро-лайт + C + E + F | B21: Осторожный | C21: =R_комбо!AM8 -> 927065.89 | D21: =R_комбо!AN8 -> 1835533.4 | E21: =R_комбо!AO8 -> 3128536.1 | F21: =R_комбо!AO12 -> -6951423 | G21: =R_комбо!AL12 -> -580877.3 | H21: =MIN(0,MIN(R_комбо!C15:AL15)) -> -23467518 | I21: =R_комбо!AL15 -> -23467518 | J21: =MIN(R_комбо!C16:AL16) -> 99 | K21: =MIN(R_комбо!C17:AL17) -> 99 | L21: =R_комбо!AP13 -> 2100000
A22: R. Комбо: ядро-лайт + C + E + F | B22: Базовый | C22: =R_комбо!AM23 -> 2309300.2 | D22: =R_комбо!AN23 -> 8457138.7 | E22: =R_комбо!AO23 -> 15875399 | F22: =R_комбо!AO27 -> 2368930.7 | G22: =R_комбо!AL27 -> 350434.06 | H22: =MIN(0,MIN(R_комбо!C30:AL30)) -> -8431658.3 | I22: =R_комбо!AL30 -> -6021735.2 | J22: =MIN(R_комбо!C31:AL31) -> 23 | K22: =MIN(R_комбо!C32:AL32) -> 99 | L22: =R_комбо!AP28 -> 1400000
A23: R. Комбо: ядро-лайт + C + E + F | B23: Оптимистичный | C23: =R_комбо!AM38 -> 11766272 | D23: =R_комбо!AN38 -> 42336700 | E23: =R_комбо!AO38 -> 73481294 | F23: =R_комбо!AO42 -> 51814984 | G23: =R_комбо!AL42 -> 5227371.4 | H23: =MIN(0,MIN(R_комбо!C45:AL45)) -> -2069223.2 | I23: =R_комбо!AL45 -> 81467667 | J23: =MIN(R_комбо!C46:AL46) -> 6 | K23: =MIN(R_комбо!C47:AL47) -> 10 | L23: =R_комбо!AP43 -> 970000

Sheet A_дропшиппинг
A1: A. Полный эскалатор → трафик на свои карточки Ozon (дропшиппинг FBS)
A2: Реклама в TG продаётся только при ≥10 тыс. подписчиков (порог реестра РКН, 303-ФЗ: канал нужно зарегистрировать).
A4: Сценарий: Осторожный | B4: Месяц → | C4: 1 | D4: 2 | E4: 3 | F4: 4 | G4: 5 | H4: 6 | I4: 7 | J4: 8 | K4: 9 | L4: 10 | M4: 11 | N4: 12 | O4: 13 | P4: 14 | Q4: 15 | R4: 16 | S4: 17 | T4: 18 | U4: 19 | V4: 20 | W4: 21 | X4: 22 | Y4: 23 | Z4: 24 | AA4: 25 | AB4: 26 | AC4: 27 | AD4: 28 | AE4: 29 | AF4: 30 | AG4: 31 | AH4: 32 | AI4: 33 | AJ4: 34 | AK4: 35 | AL4: 36 | AM4: Год 1 | AN4: Год 2 | AO4: Год 3 | AP4: Итого 36 мес
A5: visits | B5: Визиты сайта | C5: =Допущения!$C$21*IF(C$4<Допущения!$C$27,0,((C$4-Допущения!$C$27+1)/(36-Допущения!$C$27+1))^Допущения!$C$28) -> 0 | D5: =Допущения!$C$21*IF(D$4<Допущения!$C$27,0,((D$4-Допущения!$C$27+1)/(36-Допущения!$C$27+1))^Допущения!$C$28) -> 0 | E5: =Допущения!$C$21*IF(E$4<Допущения!$C$27,0,((E$4-Допущения!$C$27+1)/(36-Допущения!$C$27+1))^Допущения!$C$28) -> 302.64456 | F5: =Допущения!$C$21*IF(F$4<Допущения!$C$27,0,((F$4-Допущения!$C$27+1)/(36-Допущения!$C$27+1))^Допущения!$C$28) -> 856.00809 | G5: =Допущения!$C$21*IF(G$4<Допущения!$C$27,0,((G$4-Допущения!$C$27+1)/(36-Допущения!$C$27+1))^Допущения!$C$28) -> 1572.5873 | H5: =Допущения!$C$21*IF(H$4<Допущения!$C$27,0,((H$4-Допущения!$C$27+1)/(36-Допущения!$C$27+1))^Допущения!$C$28) -> 2421.1565 | I5: =Допущения!$C$21*IF(I$4<Допущения!$C$27,0,((I$4-Допущения!$C$27+1)/(36-Допущения!$C$27+1))^Допущения!$C$28) -> 3383.6691 | J5: =Допущения!$C$21*IF(J$4<Допущения!$C$27,0,((J$4-Допущения!$C$27+1)/(36-Допущения!$C$27+1))^Допущения!$C$28) -> 4447.9485 | ... AL5: =Допущения!$C$21*IF(AL$4<Допущения!$C$27,0,((AL$4-Допущения!$C$27+1)/(36-Допущения!$C$27+1))^Допущения!$C$28) -> 60000 | AM5: =SUM(C5:N5) -> 43178.999 | AN5: =SUM(O5:Z5) -> 247426.33 | AO5: =SUM(AA5:AL5) -> 555607.55 | AP5: =SUM(C5:AL5) -> 846212.88
A6: subs | B6: Подписчики Telegram (на конец мес.) | C6: =Допущения!$C$22*IF(C$4<Допущения!$C$27,0,((C$4-Допущения!$C$27+1)/(36-Допущения!$C$27+1))^Допущения!$C$28) -> 0 | D6: =Допущения!$C$22*IF(D$4<Допущения!$C$27,0,((D$4-Допущения!$C$27+1)/(36-Допущения!$C$27+1))^Допущения!$C$28) -> 0 | E6: =Допущения!$C$22*IF(E$4<Допущения!$C$27,0,((E$4-Допущения!$C$27+1)/(36-Допущения!$C$27+1))^Допущения!$C$28) -> 50.44076 | F6: =Допущения!$C$22*IF(F$4<Допущения!$C$27,0,((F$4-Допущения!$C$27+1)/(36-Допущения!$C$27+1))^Допущения!$C$28) -> 142.66801 | G6: =Допущения!$C$22*IF(G$4<Допущения!$C$27,0,((G$4-Допущения!$C$27+1)/(36-Допущения!$C$27+1))^Допущения!$C$28) -> 262.09788 | H6: =Допущения!$C$22*IF(H$4<Допущения!$C$27,0,((H$4-Допущения!$C$27+1)/(36-Допущения!$C$27+1))^Допущения!$C$28) -> 403.52608 | I6: =Допущения!$C$22*IF(I$4<Допущения!$C$27,0,((I$4-Допущения!$C$27+1)/(36-Допущения!$C$27+1))^Допущения!$C$28) -> 563.94484 | J6: =Допущения!$C$22*IF(J$4<Допущения!$C$27,0,((J$4-Допущения!$C$27+1)/(36-Допущения!$C$27+1))^Допущения!$C$28) -> 741.32475 | ... AL6: =Допущения!$C$22*IF(AL$4<Допущения!$C$27,0,((AL$4-Допущения!$C$27+1)/(36-Допущения!$C$27+1))^Допущения!$C$28) -> 10000 | AM6: =N6 -> 1595.0769 | AN6: =Z6 -> 5204.939 | AO6: =AL6 -> 10000
A7: clips | B7: Просмотры клипов | C7: =Допущения!$C$23*IF(C$4<Допущения!$C$27,0,((C$4-Допущения!$C$27+1)/(36-Допущения!$C$27+1))^Допущения!$C$28) -> 0 | D7: =Допущения!$C$23*IF(D$4<Допущения!$C$27,0,((D$4-Допущения!$C$27+1)/(36-Допущения!$C$27+1))^Допущения!$C$28) -> 0 | E7: =Допущения!$C$23*IF(E$4<Допущения!$C$27,0,((E$4-Допущения!$C$27+1)/(36-Допущения!$C$27+1))^Допущения!$C$28) -> 10088.152 | F7: =Допущения!$C$23*IF(F$4<Допущения!$C$27,0,((F$4-Допущения!$C$27+1)/(36-Допущения!$C$27+1))^Допущения!$C$28) -> 28533.603 | G7: =Допущения!$C$23*IF(G$4<Допущения!$C$27,0,((G$4-Допущения!$C$27+1)/(36-Допущения!$C$27+1))^Допущения!$C$28) -> 52419.576 | H7: =Допущения!$C$23*IF(H$4<Допущения!$C$27,0,((H$4-Допущения!$C$27+1)/(36-Допущения!$C$27+1))^Допущения!$C$28) -> 80705.217 | I7: =Допущения!$C$23*IF(I$4<Допущения!$C$27,0,((I$4-Допущения!$C$27+1)/(36-Допущения!$C$27+1))^Допущения!$C$28) -> 112788.97 | J7: =Допущения!$C$23*IF(J$4<Допущения!$C$27,0,((J$4-Допущения!$C$27+1)/(36-Допущения!$C$27+1))^Допущения!$C$28) -> 148264.95 | ... AL7: =Допущения!$C$23*IF(AL$4<Допущения!$C$27,0,((AL$4-Допущения!$C$27+1)/(36-Допущения!$C$27+1))^Допущения!$C$28) -> 2000000 | AM7: =SUM(C7:N7) -> 1439300 | AN7: =SUM(O7:Z7) -> 8247544.3 | AO7: =SUM(AA7:AL7) -> 18520252 | AP7: =SUM(C7:AL7) -> 28207096
A8: clicks | B8: Клики на Ozon | C8: =C5*Допущения!$C$24+C6*Допущения!$C$25+C7*Допущения!$C$26 -> 0 | D8: =D5*Допущения!$C$24+D6*Допущения!$C$25+D7*Допущения!$C$26 -> 0 | E8: =E5*Допущения!$C$24+E6*Допущения!$C$25+E7*Допущения!$C$26 -> 10.088152 | F8: =F5*Допущения!$C$24+F6*Допущения!$C$25+F7*Допущения!$C$26 -> 28.533603 | G8: =G5*Допущения!$C$24+G6*Допущения!$C$25+G7*Допущения!$C$26 -> 52.419576 | H8: =H5*Допущения!$C$24+H6*Допущения!$C$25+H7*Допущения!$C$26 -> 80.705217 | I8: =I5*Допущения!$C$24+I6*Допущения!$C$25+I7*Допущения!$C$26 -> 112.78897 | J8: =J5*Допущения!$C$24+J6*Допущения!$C$25+J7*Допущения!$C$26 -> 148.26495 | ... AL8: =AL5*Допущения!$C$24+AL6*Допущения!$C$25+AL7*Допущения!$C$26 -> 2000 | AM8: =SUM(C8:N8) -> 1439.3 | AN8: =SUM(O8:Z8) -> 8247.5443 | AO8: =SUM(AA8:AL8) -> 18520.252 | AP8: =SUM(C8:AL8) -> 28207.096
A9: orders | B9: Заказы (с «эффектом Ozon») | C9: =C8*Допущения!$C$6*Допущения!$C$7 -> 0 | D9: =D8*Допущения!$C$6*Допущения!$C$7 -> 0 | E9: =E8*Допущения!$C$6*Допущения!$C$7 -> 0.20176304 | F9: =F8*Допущения!$C$6*Допущения!$C$7 -> 0.57067206 | G9: =G8*Допущения!$C$6*Допущения!$C$7 -> 1.0483915 | H9: =H8*Допущения!$C$6*Допущения!$C$7 -> 1.6141043 | I9: =I8*Допущения!$C$6*Допущения!$C$7 -> 2.2557794 | J9: =J8*Допущения!$C$6*Допущения!$C$7 -> 2.965299 | ... AL9: =AL8*Допущения!$C$6*Допущения!$C$7 -> 40 | AM9: =SUM(C9:N9) -> 28.785999 | AN9: =SUM(O9:Z9) -> 164.95089 | AO9: =SUM(AA9:AL9) -> 370.40503 | AP9: =SUM(C9:AL9) -> 564.14192
A10: rev | B10: Оборот на Ozon, ₽ | C10: =C9*Допущения!$C$4 -> 0 | D10: =D9*Допущения!$C$4 -> 0 | E10: =E9*Допущения!$C$4 -> 262.29195 | F10: =F9*Допущения!$C$4 -> 741.87368 | G10: =G9*Допущения!$C$4 -> 1362.909 | H10: =H9*Допущения!$C$4 -> 2098.3356 | I10: =I9*Допущения!$C$4 -> 2932.5132 | J10: =J9*Допущения!$C$4 -> 3854.8887 | ... AL10: =AL9*Допущения!$C$4 -> 52000 | AM10: =SUM(C10:N10) -> 37421.799 | AN10: =SUM(O10:Z10) -> 214436.15 | AO10: =SUM(AA10:AL10) -> 481526.54 | AP10: =SUM(C10:AL10) -> 733384.49
A11: c_comm | B11: Маржа дропшиппинга | C11: =C10*Допущения!$C$5 -> 0 | D11: =D10*Допущения!$C$5 -> 0 | E11: =E10*Допущения!$C$5 -> 20.983356 | F11: =F10*Допущения!$C$5 -> 59.349894 | G11: =G10*Допущения!$C$5 -> 109.03272 | H11: =H10*Допущения!$C$5 -> 167.86685 | I11: =I10*Допущения!$C$5 -> 234.60106 | J11: =J10*Допущения!$C$5 -> 308.3911 | ... AL11: =AL10*Допущения!$C$5 -> 4160 | AM11: =SUM(C11:N11) -> 2993.7439 | AN11: =SUM(O11:Z11) -> 17154.892 | AO11: =SUM(AA11:AL11) -> 38522.123 | AP11: =SUM(C11:AL11) -> 58670.759
A12: c_rsya | B12: РСЯ на сайте | C12: =C5/1000*Допущения!$C$8 -> 0 | D12: =D5/1000*Допущения!$C$8 -> 0 | E12: =E5/1000*Допущения!$C$8 -> 12.105782 | F12: =F5/1000*Допущения!$C$8 -> 34.240324 | G12: =G5/1000*Допущения!$C$8 -> 62.903491 | H12: =H5/1000*Допущения!$C$8 -> 96.84626 | I12: =I5/1000*Допущения!$C$8 -> 135.34676 | J12: =J5/1000*Допущения!$C$8 -> 177.91794 | ... AL12: =AL5/1000*Допущения!$C$8 -> 2400 | AM12: =SUM(C12:N12) -> 1727.16 | AN12: =SUM(O12:Z12) -> 9897.0531 | AO12: =SUM(AA12:AL12) -> 22224.302 | AP12: =SUM(C12:AL12) -> 33848.515
A13: c_tg | B13: Реклама в своём Telegram (за вычетом налога) | C13: =IF(C6>=10000,C6*Допущения!$C$11*Допущения!$C$10/1000*Допущения!$C$12*(1-Допущения!$C$14),0) -> 0 | D13: =IF(D6>=10000,D6*Допущения!$C$11*Допущения!$C$10/1000*Допущения!$C$12*(1-Допущения!$C$14),0) -> 0 | E13: =IF(E6>=10000,E6*Допущения!$C$11*Допущения!$C$10/1000*Допущения!$C$12*(1-Допущения!$C$14),0) -> 0 | F13: =IF(F6>=10000,F6*Допущения!$C$11*Допущения!$C$10/1000*Допущения!$C$12*(1-Допущения!$C$14),0) -> 0 | G13: =IF(G6>=10000,G6*Допущения!$C$11*Допущения!$C$10/1000*Допущения!$C$12*(1-Допущения!$C$14),0) -> 0 | H13: =IF(H6>=10000,H6*Допущения!$C$11*Допущения!$C$10/1000*Допущения!$C$12*(1-Допущения!$C$14),0) -> 0 | I13: =IF(I6>=10000,I6*Допущения!$C$11*Допущения!$C$10/1000*Допущения!$C$12*(1-Допущения!$C$14),0) -> 0 | J13: =IF(J6>=10000,J6*Допущения!$C$11*Допущения!$C$10/1000*Допущения!$C$12*(1-Допущения!$C$14),0) -> 0 | ... AL13: =IF(AL6>=10000,AL6*Допущения!$C$11*Допущения!$C$10/1000*Допущения!$C$12*(1-Допущения!$C$14),0) -> 2481.6 | AM13: =SUM(C13:N13) -> 0 | AN13: =SUM(O13:Z13) -> 0 | AO13: =SUM(AA13:AL13) -> 2481.6 | AP13: =SUM(C13:AL13) -> 2481.6
A14: contrib | B14: Маржинальный доход | C14: =C11+C12+C13 -> 0 | D14: =D11+D12+D13 -> 0 | E14: =E11+E12+E13 -> 33.089139 | F14: =F11+F12+F13 -> 93.590218 | G14: =G11+G12+G13 -> 171.93621 | H14: =H11+H12+H13 -> 264.71311 | I14: =I11+I12+I13 -> 369.94782 | J14: =J11+J12+J13 -> 486.30904 | ... AL14: =AL11+AL12+AL13 -> 9041.6 | AM14: =SUM(C14:N14) -> 4720.9039 | AN14: =SUM(O14:Z14) -> 27051.945 | AO14: =SUM(AA14:AL14) -> 63228.025 | AP14: =SUM(C14:AL14) -> 95000.874
A15: acq | B15: Покупка подписчиков Telegram | C15: =MAX(0,C6-0)*(1-Допущения!$C$13)*Допущения!$C$9 -> 0 | D15: =MAX(0,D6-C6)*(1-Допущения!$C$13)*Допущения!$C$9 -> 0 | E15: =MAX(0,E6-D6)*(1-Допущения!$C$13)*Допущения!$C$9 -> 12105.782 | F15: =MAX(0,F6-E6)*(1-Допущения!$C$13)*Допущения!$C$9 -> 22134.541 | G15: =MAX(0,G6-F6)*(1-Допущения!$C$13)*Допущения!$C$9 -> 28663.167 | H15: =MAX(0,H6-G6)*(1-Допущения!$C$13)*Допущения!$C$9 -> 33942.769 | I15: =MAX(0,I6-H6)*(1-Допущения!$C$13)*Допущения!$C$9 -> 38500.503 | J15: =MAX(0,J6-I6)*(1-Допущения!$C$13)*Допущения!$C$9 -> 42571.177 | K15: =MAX(0,K6-J6)*(1-Допущения!$C$13)*Допущения!$C$9 -> 46284.289 | ... AL15: =MAX(0,AL6-AK6)*(1-Допущения!$C$13)*Допущения!$C$9 -> 105099.95 | AM15: =SUM(C15:N15) -> 382818.45 | AN15: =SUM(O15:Z15) -> 866366.91 | AO15: =SUM(AA15:AL15) -> 1150814.6 | AP15: =SUM(C15:AL15) -> 2400000
A16: fixed | B16: Постоянные расходы (команда) | C16: =Допущения!$C$16 -> 480000 | D16: =Допущения!$C$16 -> 480000 | E16: =Допущения!$C$16 -> 480000 | F16: =Допущения!$C$16 -> 480000 | G16: =Допущения!$C$16 -> 480000 | H16: =Допущения!$C$16 -> 480000 | I16: =Допущения!$C$16 -> 480000 | J16: =Допущения!$C$16 -> 480000 | ... AL16: =Допущения!$C$16 -> 480000 | AM16: =SUM(C16:N16) -> 5760000 | AN16: =SUM(O16:Z16) -> 5760000 | AO16: =SUM(AA16:AL16) -> 5760000 | AP16: =SUM(C16:AL16) -> 17280000
A17: op | B17: Операционная прибыль (маржинальный доход − постоянные − привлечение) | C17: =C14-C16-C15 -> -480000 | D17: =D14-D16-D15 -> -480000 | E17: =E14-E16-E15 -> -492072.69 | F17: =F14-F16-F15 -> -502040.95 | G17: =G14-G16-G15 -> -508491.23 | H17: =H14-H16-H15 -> -513678.06 | I17: =I14-I16-I15 -> -518130.56 | J17: =J14-J16-J15 -> -522084.87 | ... AL17: =AL14-AL16-AL15 -> -576058.35 | AM17: =SUM(C17:N17) -> -6138097.6 | AN17: =SUM(O17:Z17) -> -6599315 | AO17: =SUM(AA17:AL17) -> -6847586.6 | AP17: =SUM(C17:AL17) -> -19584999
A18: capex | B18: CAPEX и вложения в оборотку | C18: =IF(C$4=1,Допущения!$C$18,0) -> 600000 | D18: =IF(D$4=1,Допущения!$C$18,0) -> 0 | E18: =IF(E$4=1,Допущения!$C$18,0) -> 0 | F18: =IF(F$4=1,Допущения!$C$18,0) -> 0 | G18: =IF(G$4=1,Допущения!$C$18,0) -> 0 | H18: =IF(H$4=1,Допущения!$C$18,0) -> 0 | I18: =IF(I$4=1,Допущения!$C$18,0) -> 0 | J18: =IF(J$4=1,Допущения!$C$18,0) -> 0 | ... AL18: =IF(AL$4=1,Допущения!$C$18,0) -> 0 | AM18: =SUM(C18:N18) -> 600000 | AN18: =SUM(O18:Z18) -> 0 | AO18: =SUM(AA18:AL18) -> 0 | AP18: =SUM(C18:AL18) -> 600000
A19: cf | B19: Денежный поток | C19: =C17-C18 -> -1080000 | D19: =D17-D18 -> -480000 | E19: =E17-E18 -> -492072.69 | F19: =F17-F18 -> -502040.95 | G19: =G17-G18 -> -508491.23 | H19: =H17-H18 -> -513678.06 | I19: =I17-I18 -> -518130.56 | J19: =J17-J18 -> -522084.87 | ... AL19: =AL17-AL18 -> -576058.35 | AM19: =SUM(C19:N19) -> -6738097.6 | AN19: =SUM(O19:Z19) -> -6599315 | AO19: =SUM(AA19:AL19) -> -6847586.6 | AP19: =SUM(C19:AL19) -> -20184999
A20: cum | B20: Накопленный денежный поток | C20: =0+C19 -> -1080000 | D20: =C20+D19 -> -1560000 | E20: =D20+E19 -> -2052072.7 | F20: =E20+F19 -> -2554113.6 | G20: =F20+G19 -> -3062604.9 | H20: =G20+H19 -> -3576282.9 | I20: =H20+I19 -> -4094413.5 | J20: =I20+J19 -> -4616498.4 | K20: =J20+K19 -> -5142169.8 | ... AL20: =AK20+AL19 -> -20184999 | AM20: =N20 -> -6738097.6 | AN20: =Z20 -> -13337413 | AO20: =AL20 -> -20184999
A21: be_flag | B21: служебно: месяц устойчивой опер. прибыли | C21: =IF(AND(C17>0,COUNTIF(C17:AL17,"<=0")=0),C$4,99) -> 99 | D21: =IF(AND(D17>0,COUNTIF(D17:AL17,"<=0")=0),D$4,99) -> 99 | E21: =IF(AND(E17>0,COUNTIF(E17:AL17,"<=0")=0),E$4,99) -> 99 | F21: =IF(AND(F17>0,COUNTIF(F17:AL17,"<=0")=0),F$4,99) -> 99 | G21: =IF(AND(G17>0,COUNTIF(G17:AL17,"<=0")=0),G$4,99) -> 99 | H21: =IF(AND(H17>0,COUNTIF(H17:AL17,"<=0")=0),H$4,99) -> 99 | I21: =IF(AND(I17>0,COUNTIF(I17:AL17,"<=0")=0),I$4,99) -> 99 | J21: =IF(AND(J17>0,COUNTIF(J17:AL17,"<=0")=0),J$4,99) -> 99 | K21: =IF(AND(K17>0,COUNTIF(K17:AL17,"<=0")=0),K$4,99) -> 99 | L21: =IF(AND(L17>0,COUNTIF(L17:AL17,"<=0")=0),L$4,99) -> 99 | M21: =IF(AND(M17>0,COUNTIF(M17:AL17,"<=0")=0),M$4,99) -> 99 | N21: =IF(AND(N17>0,COUNTIF(N17:AL17,"<=0")=0),N$4,99) -> 99 | O21: =IF(AND(O17>0,COUNTIF(O17:AL17,"<=0")=0),O$4,99) -> 99 | P21: =IF(AND(P17>0,COUNTIF(P17:AL17,"<=0")=0),P$4,99) -> 99 | Q21: =IF(AND(Q17>0,COUNTIF(Q17:AL17,"<=0")=0),Q$4,99) -> 99 | R21: =IF(AND(R17>0,COUNTIF(R17:AL17,"<=0")=0),R$4,99) -> 99 | S21: =IF(AND(S17>0,COUNTIF(S17:AL17,"<=0")=0),S$4,99) -> 99 | T21: =IF(AND(T17>0,COUNTIF(T17:AL17,"<=0")=0),T$4,99) -> 99 | U21: =IF(AND(U17>0,COUNTIF(U17:AL17,"<=0")=0),U$4,99) -> 99 | V21: =IF(AND(V17>0,COUNTIF(V17:AL17,"<=0")=0),V$4,99) -> 99 | W21: =IF(AND(W17>0,COUNTIF(W17:AL17,"<=0")=0),W$4,99) -> 99 | X21: =IF(AND(X17>0,COUNTIF(X17:AL17,"<=0")=0),X$4,99) -> 99 | Y21: =IF(AND(Y17>0,COUNTIF(Y17:AL17,"<=0")=0),Y$4,99) -> 99 | Z21: =IF(AND(Z17>0,COUNTIF(Z17:AL17,"<=0")=0),Z$4,99) -> 99 | AA21: =IF(AND(AA17>0,COUNTIF(AA17:AL17,"<=0")=0),AA$4,99) -> 99 | AB21: =IF(AND(AB17>0,COUNTIF(AB17:AL17,"<=0")=0),AB$4,99) -> 99 | AC21: =IF(AND(AC17>0,COUNTIF(AC17:AL17,"<=0")=0),AC$4,99) -> 99 | AD21: =IF(AND(AD17>0,COUNTIF(AD17:AL17,"<=0")=0),AD$4,99) -> 99 | AE21: =IF(AND(AE17>0,COUNTIF(AE17:AL17,"<=0")=0),AE$4,99) -> 99 | AF21: =IF(AND(AF17>0,COUNTIF(AF17:AL17,"<=0")=0),AF$4,99) -> 99 | AG21: =IF(AND(AG17>0,COUNTIF(AG17:AL17,"<=0")=0),AG$4,99) -> 99 | AH21: =IF(AND(AH17>0,COUNTIF(AH17:AL17,"<=0")=0),AH$4,99) -> 99 | AI21: =IF(AND(AI17>0,COUNTIF(AI17:AL17,"<=0")=0),AI$4,99) -> 99 | AJ21: =IF(AND(AJ17>0,COUNTIF(AJ17:AL17,"<=0")=0),AJ$4,99) -> 99 | AK21: =IF(AND(AK17>0,COUNTIF(AK17:AL17,"<=0")=0),AK$4,99) -> 99 | AL21: =IF(AND(AL17>0,COUNTIF(AL17:AL17,"<=0")=0),AL$4,99) -> 99
A22: pb_flag | B22: служебно: месяц окупаемости | C22: =IF(AND(C20>=0,COUNTIF(C20:AL20,"<0")=0),C$4,99) -> 99 | D22: =IF(AND(D20>=0,COUNTIF(D20:AL20,"<0")=0),D$4,99) -> 99 | E22: =IF(AND(E20>=0,COUNTIF(E20:AL20,"<0")=0),E$4,99) -> 99 | F22: =IF(AND(F20>=0,COUNTIF(F20:AL20,"<0")=0),F$4,99) -> 99 | G22: =IF(AND(G20>=0,COUNTIF(G20:AL20,"<0")=0),G$4,99) -> 99 | H22: =IF(AND(H20>=0,COUNTIF(H20:AL20,"<0")=0),H$4,99) -> 99 | I22: =IF(AND(I20>=0,COUNTIF(I20:AL20,"<0")=0),I$4,99) -> 99 | J22: =IF(AND(J20>=0,COUNTIF(J20:AL20,"<0")=0),J$4,99) -> 99 | K22: =IF(AND(K20>=0,COUNTIF(K20:AL20,"<0")=0),K$4,99) -> 99 | L22: =IF(AND(L20>=0,COUNTIF(L20:AL20,"<0")=0),L$4,99) -> 99 | M22: =IF(AND(M20>=0,COUNTIF(M20:AL20,"<0")=0),M$4,99) -> 99 | N22: =IF(AND(N20>=0,COUNTIF(N20:AL20,"<0")=0),N$4,99) -> 99 | O22: =IF(AND(O20>=0,COUNTIF(O20:AL20,"<0")=0),O$4,99) -> 99 | P22: =IF(AND(P20>=0,COUNTIF(P20:AL20,"<0")=0),P$4,99) -> 99 | Q22: =IF(AND(Q20>=0,COUNTIF(Q20:AL20,"<0")=0),Q$4,99) -> 99 | R22: =IF(AND(R20>=0,COUNTIF(R20:AL20,"<0")=0),R$4,99) -> 99 | S22: =IF(AND(S20>=0,COUNTIF(S20:AL20,"<0")=0),S$4,99) -> 99 | T22: =IF(AND(T20>=0,COUNTIF(T20:AL20,"<0")=0),T$4,99) -> 99 | U22: =IF(AND(U20>=0,COUNTIF(U20:AL20,"<0")=0),U$4,99) -> 99 | V22: =IF(AND(V20>=0,COUNTIF(V20:AL20,"<0")=0),V$4,99) -> 99 | W22: =IF(AND(W20>=0,COUNTIF(W20:AL20,"<0")=0),W$4,99) -> 99 | X22: =IF(AND(X20>=0,COUNTIF(X20:AL20,"<0")=0),X$4,99) -> 99 | Y22: =IF(AND(Y20>=0,COUNTIF(Y20:AL20,"<0")=0),Y$4,99) -> 99 | Z22: =IF(AND(Z20>=0,COUNTIF(Z20:AL20,"<0")=0),Z$4,99) -> 99 | AA22: =IF(AND(AA20>=0,COUNTIF(AA20:AL20,"<0")=0),AA$4,99) -> 99 | AB22: =IF(AND(AB20>=0,COUNTIF(AB20:AL20,"<0")=0),AB$4,99) -> 99 | AC22: =IF(AND(AC20>=0,COUNTIF(AC20:AL20,"<0")=0),AC$4,99) -> 99 | AD22: =IF(AND(AD20>=0,COUNTIF(AD20:AL20,"<0")=0),AD$4,99) -> 99 | AE22: =IF(AND(AE20>=0,COUNTIF(AE20:AL20,"<0")=0),AE$4,99) -> 99 | AF22: =IF(AND(AF20>=0,COUNTIF(AF20:AL20,"<0")=0),AF$4,99) -> 99 | AG22: =IF(AND(AG20>=0,COUNTIF(AG20:AL20,"<0")=0),AG$4,99) -> 99 | AH22: =IF(AND(AH20>=0,COUNTIF(AH20:AL20,"<0")=0),AH$4,99) -> 99 | AI22: =IF(AND(AI20>=0,COUNTIF(AI20:AL20,"<0")=0),AI$4,99) -> 99 | AJ22: =IF(AND(AJ20>=0,COUNTIF(AJ20:AL20,"<0")=0),AJ$4,99) -> 99 | AK22: =IF(AND(AK20>=0,COUNTIF(AK20:AL20,"<0")=0),AK$4,99) -> 99 | AL22: =IF(AND(AL20>=0,COUNTIF(AL20:AL20,"<0")=0),AL$4,99) -> 99
A24: Сценарий: Базовый | B24: Месяц → | C24: 1 | D24: 2 | E24: 3 | F24: 4 | G24: 5 | H24: 6 | I24: 7 | J24: 8 | K24: 9 | L24: 10 | M24: 11 | N24: 12 | O24: 13 | P24: 14 | Q24: 15 | R24: 16 | S24: 17 | T24: 18 | U24: 19 | V24: 20 | W24: 21 | X24: 22 | Y24: 23 | Z24: 24 | AA24: 25 | AB24: 26 | AC24: 27 | AD24: 28 | AE24: 29 | AF24: 30 | AG24: 31 | AH24: 32 | AI24: 33 | AJ24: 34 | AK24: 35 | AL24: 36 | AM24: Год 1 | AN24: Год 2 | AO24: Год 3 | AP24: Итого 36 мес
A25: visits | B25: Визиты сайта | C25: =Допущения!$D$21*IF(C$24<Допущения!$D$27,0,((C$24-Допущения!$D$27+1)/(36-Допущения!$D$27+1))^Допущения!$D$28) -> 0 | D25: =Допущения!$D$21*IF(D$24<Допущения!$D$27,0,((D$24-Допущения!$D$27+1)/(36-Допущения!$D$27+1))^Допущения!$D$28) -> 0 | E25: =Допущения!$D$21*IF(E$24<Допущения!$D$27,0,((E$24-Допущения!$D$27+1)/(36-Допущения!$D$27+1))^Допущения!$D$28) -> 1531.6822 | F25: =Допущения!$D$21*IF(F$24<Допущения!$D$27,0,((F$24-Допущения!$D$27+1)/(36-Допущения!$D$27+1))^Допущения!$D$28) -> 3771.444 | G25: =Допущения!$D$21*IF(G$24<Допущения!$D$27,0,((G$24-Допущения!$D$27+1)/(36-Допущения!$D$27+1))^Допущения!$D$28) -> 6388.9031 | H25: =Допущения!$D$21*IF(H$24<Допущения!$D$27,0,((H$24-Допущения!$D$27+1)/(36-Допущения!$D$27+1))^Допущения!$D$28) -> 9286.3844 | I25: =Допущения!$D$21*IF(I$24<Допущения!$D$27,0,((I$24-Допущения!$D$27+1)/(36-Допущения!$D$27+1))^Допущения!$D$28) -> 12411.654 | J25: =Допущения!$D$21*IF(J$24<Допущения!$D$27,0,((J$24-Допущения!$D$27+1)/(36-Допущения!$D$27+1))^Допущения!$D$28) -> 15731.325 | ... AL25: =Допущения!$D$21*IF(AL$24<Допущения!$D$27,0,((AL$24-Допущения!$D$27+1)/(36-Допущения!$D$27+1))^Допущения!$D$28) -> 150000 | AM25: =SUM(C25:N25) -> 148419.31 | AN25: =SUM(O25:Z25) -> 709250.31 | AO25: =SUM(AA25:AL25) -> 1435133.1 | AP25: =SUM(C25:AL25) -> 2292802.7
A26: subs | B26: Подписчики Telegram (на конец мес.) | C26: =Допущения!$D$22*IF(C$24<Допущения!$D$27,0,((C$24-Допущения!$D$27+1)/(36-Допущения!$D$27+1))^Допущения!$D$28) -> 0 | D26: =Допущения!$D$22*IF(D$24<Допущения!$D$27,0,((D$24-Допущения!$D$27+1)/(36-Допущения!$D$27+1))^Допущения!$D$28) -> 0 | E26: =Допущения!$D$22*IF(E$24<Допущения!$D$27,0,((E$24-Допущения!$D$27+1)/(36-Допущения!$D$27+1))^Допущения!$D$28) -> 255.28037 | F26: =Допущения!$D$22*IF(F$24<Допущения!$D$27,0,((F$24-Допущения!$D$27+1)/(36-Допущения!$D$27+1))^Допущения!$D$28) -> 628.574 | G26: =Допущения!$D$22*IF(G$24<Допущения!$D$27,0,((G$24-Допущения!$D$27+1)/(36-Допущения!$D$27+1))^Допущения!$D$28) -> 1064.8172 | H26: =Допущения!$D$22*IF(H$24<Допущения!$D$27,0,((H$24-Допущения!$D$27+1)/(36-Допущения!$D$27+1))^Допущения!$D$28) -> 1547.7307 | I26: =Допущения!$D$22*IF(I$24<Допущения!$D$27,0,((I$24-Допущения!$D$27+1)/(36-Допущения!$D$27+1))^Допущения!$D$28) -> 2068.6091 | J26: =Допущения!$D$22*IF(J$24<Допущения!$D$27,0,((J$24-Допущения!$D$27+1)/(36-Допущения!$D$27+1))^Допущения!$D$28) -> 2621.8874 | ... AL26: =Допущения!$D$22*IF(AL$24<Допущения!$D$27,0,((AL$24-Допущения!$D$27+1)/(36-Допущения!$D$27+1))^Допущения!$D$28) -> 25000 | AM26: =N26 -> 5093.513 | AN26: =Z26 -> 14196.03 | AO26: =AL26 -> 25000
A27: clips | B27: Просмотры клипов | C27: =Допущения!$D$23*IF(C$24<Допущения!$D$27,0,((C$24-Допущения!$D$27+1)/(36-Допущения!$D$27+1))^Допущения!$D$28) -> 0 | D27: =Допущения!$D$23*IF(D$24<Допущения!$D$27,0,((D$24-Допущения!$D$27+1)/(36-Допущения!$D$27+1))^Допущения!$D$28) -> 0 | E27: =Допущения!$D$23*IF(E$24<Допущения!$D$27,0,((E$24-Допущения!$D$27+1)/(36-Допущения!$D$27+1))^Допущения!$D$28) -> 61267.288 | F27: =Допущения!$D$23*IF(F$24<Допущения!$D$27,0,((F$24-Допущения!$D$27+1)/(36-Допущения!$D$27+1))^Допущения!$D$28) -> 150857.76 | G27: =Допущения!$D$23*IF(G$24<Допущения!$D$27,0,((G$24-Допущения!$D$27+1)/(36-Допущения!$D$27+1))^Допущения!$D$28) -> 255556.12 | H27: =Допущения!$D$23*IF(H$24<Допущения!$D$27,0,((H$24-Допущения!$D$27+1)/(36-Допущения!$D$27+1))^Допущения!$D$28) -> 371455.37 | I27: =Допущения!$D$23*IF(I$24<Допущения!$D$27,0,((I$24-Допущения!$D$27+1)/(36-Допущения!$D$27+1))^Допущения!$D$28) -> 496466.17 | J27: =Допущения!$D$23*IF(J$24<Допущения!$D$27,0,((J$24-Допущения!$D$27+1)/(36-Допущения!$D$27+1))^Допущения!$D$28) -> 629252.98 | ... AL27: =Допущения!$D$23*IF(AL$24<Допущения!$D$27,0,((AL$24-Допущения!$D$27+1)/(36-Допущения!$D$27+1))^Допущения!$D$28) -> 6000000 | AM27: =SUM(C27:N27) -> 5936772.3 | AN27: =SUM(O27:Z27) -> 28370012 | AO27: =SUM(AA27:AL27) -> 57405322 | AP27: =SUM(C27:AL27) -> 91712107
A28: clicks | B28: Клики на Ozon | C28: =C25*Допущения!$D$24+C26*Допущения!$D$25+C27*Допущения!$D$26 -> 0 | D28: =D25*Допущения!$D$24+D26*Допущения!$D$25+D27*Допущения!$D$26 -> 0 | E28: =E25*Допущения!$D$24+E26*Допущения!$D$25+E27*Допущения!$D$26 -> 113.34448 | F28: =F25*Допущения!$D$24+F26*Допущения!$D$25+F27*Допущения!$D$26 -> 279.08685 | G28: =G25*Допущения!$D$24+G26*Допущения!$D$25+G27*Допущения!$D$26 -> 472.77883 | H28: =H25*Допущения!$D$24+H26*Допущения!$D$25+H27*Допущения!$D$26 -> 687.19244 | I28: =I25*Допущения!$D$24+I26*Допущения!$D$25+I27*Допущения!$D$26 -> 918.46242 | J28: =J25*Допущения!$D$24+J26*Допущения!$D$25+J27*Допущения!$D$26 -> 1164.118 | ... AL28: =AL25*Допущения!$D$24+AL26*Допущения!$D$25+AL27*Допущения!$D$26 -> 11100 | AM28: =SUM(C28:N28) -> 10983.029 | AN28: =SUM(O28:Z28) -> 52484.523 | AO28: =SUM(AA28:AL28) -> 106199.85 | AP28: =SUM(C28:AL28) -> 169667.4
A29: orders | B29: Заказы (с «эффектом Ozon») | C29: =C28*Допущения!$D$6*Допущения!$D$7 -> 0 | D29: =D28*Допущения!$D$6*Допущения!$D$7 -> 0 | E29: =E28*Допущения!$D$6*Допущения!$D$7 -> 4.5621154 | F29: =F28*Допущения!$D$6*Допущения!$D$7 -> 11.233246 | G29: =G28*Допущения!$D$6*Допущения!$D$7 -> 19.029348 | H29: =H28*Допущения!$D$6*Допущения!$D$7 -> 27.659496 | I29: =I28*Допущения!$D$6*Допущения!$D$7 -> 36.968112 | J29: =J28*Допущения!$D$6*Допущения!$D$7 -> 46.85575 | ... AL29: =AL28*Допущения!$D$6*Допущения!$D$7 -> 446.775 | AM29: =SUM(C29:N29) -> 442.06691 | AN29: =SUM(O29:Z29) -> 2112.502 | AO29: =SUM(AA29:AL29) -> 4274.5438 | AP29: =SUM(C29:AL29) -> 6829.1128
A30: rev | B30: Оборот на Ozon, ₽ | C30: =C29*Допущения!$D$4 -> 0 | D30: =D29*Допущения!$D$4 -> 0 | E30: =E29*Допущения!$D$4 -> 7299.3847 | F30: =F29*Допущения!$D$4 -> 17973.193 | G30: =G29*Допущения!$D$4 -> 30446.956 | H30: =H29*Допущения!$D$4 -> 44255.193 | I30: =I29*Допущения!$D$4 -> 59148.98 | J30: =J29*Допущения!$D$4 -> 74969.201 | ... AL30: =AL29*Допущения!$D$4 -> 714840 | AM30: =SUM(C30:N30) -> 707307.05 | AN30: =SUM(O30:Z30) -> 3380003.3 | AO30: =SUM(AA30:AL30) -> 6839270.1 | AP30: =SUM(C30:AL30) -> 10926580
A31: c_comm | B31: Маржа дропшиппинга | C31: =C30*Допущения!$D$5 -> 0 | D31: =D30*Допущения!$D$5 -> 0 | E31: =E30*Допущения!$D$5 -> 875.92617 | F31: =F30*Допущения!$D$5 -> 2156.7832 | G31: =G30*Допущения!$D$5 -> 3653.6348 | H31: =H30*Допущения!$D$5 -> 5310.6232 | I31: =I30*Допущения!$D$5 -> 7097.8776 | J31: =J30*Допущения!$D$5 -> 8996.3041 | ... AL31: =AL30*Допущения!$D$5 -> 85780.8 | AM31: =SUM(C31:N31) -> 84876.846 | AN31: =SUM(O31:Z31) -> 405600.39 | AO31: =SUM(AA31:AL31) -> 820712.41 | AP31: =SUM(C31:AL31) -> 1311189.7
A32: c_rsya | B32: РСЯ на сайте | C32: =C25/1000*Допущения!$D$8 -> 0 | D32: =D25/1000*Допущения!$D$8 -> 0 | E32: =E25/1000*Допущения!$D$8 -> 122.53458 | F32: =F25/1000*Допущения!$D$8 -> 301.71552 | G32: =G25/1000*Допущения!$D$8 -> 511.11224 | H32: =H25/1000*Допущения!$D$8 -> 742.91075 | I32: =I25/1000*Допущения!$D$8 -> 992.93235 | J32: =J25/1000*Допущения!$D$8 -> 1258.506 | ... AL32: =AL25/1000*Допущения!$D$8 -> 12000 | AM32: =SUM(C32:N32) -> 11873.545 | AN32: =SUM(O32:Z32) -> 56740.024 | AO32: =SUM(AA32:AL32) -> 114810.64 | AP32: =SUM(C32:AL32) -> 183424.21
A33: c_tg | B33: Реклама в своём Telegram (за вычетом налога) | C33: =IF(C26>=10000,C26*Допущения!$D$11*Допущения!$D$10/1000*Допущения!$D$12*(1-Допущения!$D$14),0) -> 0 | D33: =IF(D26>=10000,D26*Допущения!$D$11*Допущения!$D$10/1000*Допущения!$D$12*(1-Допущения!$D$14),0) -> 0 | E33: =IF(E26>=10000,E26*Допущения!$D$11*Допущения!$D$10/1000*Допущения!$D$12*(1-Допущения!$D$14),0) -> 0 | F33: =IF(F26>=10000,F26*Допущения!$D$11*Допущения!$D$10/1000*Допущения!$D$12*(1-Допущения!$D$14),0) -> 0 | G33: =IF(G26>=10000,G26*Допущения!$D$11*Допущения!$D$10/1000*Допущения!$D$12*(1-Допущения!$D$14),0) -> 0 | H33: =IF(H26>=10000,H26*Допущения!$D$11*Допущения!$D$10/1000*Допущения!$D$12*(1-Допущения!$D$14),0) -> 0 | I33: =IF(I26>=10000,I26*Допущения!$D$11*Допущения!$D$10/1000*Допущения!$D$12*(1-Допущения!$D$14),0) -> 0 | J33: =IF(J26>=10000,J26*Допущения!$D$11*Допущения!$D$10/1000*Допущения!$D$12*(1-Допущения!$D$14),0) -> 0 | ... AL33: =IF(AL26>=10000,AL26*Допущения!$D$11*Допущения!$D$10/1000*Допущения!$D$12*(1-Допущения!$D$14),0) -> 26320 | AM33: =SUM(C33:N33) -> 0 | AN33: =SUM(O33:Z33) -> 76773.174 | AO33: =SUM(AA33:AL33) -> 251818.01 | AP33: =SUM(C33:AL33) -> 328591.19
A34: contrib | B34: Маржинальный доход | C34: =C31+C32+C33 -> 0 | D34: =D31+D32+D33 -> 0 | E34: =E31+E32+E33 -> 998.46074 | F34: =F31+F32+F33 -> 2458.4987 | G34: =G31+G32+G33 -> 4164.747 | H34: =H31+H32+H33 -> 6053.534 | I34: =I31+I32+I33 -> 8090.8099 | J34: =J31+J32+J33 -> 10254.81 | ... AL34: =AL31+AL32+AL33 -> 124100.8 | AM34: =SUM(C34:N34) -> 96750.391 | AN34: =SUM(O34:Z34) -> 539113.59 | AO34: =SUM(AA34:AL34) -> 1187341.1 | AP34: =SUM(C34:AL34) -> 1823205.1
A35: acq | B35: Покупка подписчиков Telegram | C35: =MAX(0,C26-0)*(1-Допущения!$D$13)*Допущения!$D$9 -> 0 | D35: =MAX(0,D26-C26)*(1-Допущения!$D$13)*Допущения!$D$9 -> 0 | E35: =MAX(0,E26-D26)*(1-Допущения!$D$13)*Допущения!$D$9 -> 27570.28 | F35: =MAX(0,F26-E26)*(1-Допущения!$D$13)*Допущения!$D$9 -> 40315.712 | G35: =MAX(0,G26-F26)*(1-Допущения!$D$13)*Допущения!$D$9 -> 47114.263 | H35: =MAX(0,H26-G26)*(1-Допущения!$D$13)*Допущения!$D$9 -> 52154.664 | I35: =MAX(0,I26-H26)*(1-Допущения!$D$13)*Допущения!$D$9 -> 56254.86 | J35: =MAX(0,J26-I26)*(1-Допущения!$D$13)*Допущения!$D$9 -> 59754.064 | K35: =MAX(0,K26-J26)*(1-Допущения!$D$13)*Допущения!$D$9 -> 62830.202 | ... AL35: =MAX(0,AL26-AK26)*(1-Допущения!$D$13)*Допущения!$D$9 -> 102776.68 | AM35: =SUM(C35:N35) -> 550099.4 | AN35: =SUM(O35:Z35) -> 983071.81 | AO35: =SUM(AA35:AL35) -> 1166828.8 | AP35: =SUM(C35:AL35) -> 2700000
A36: fixed | B36: Постоянные расходы (команда) | C36: =Допущения!$D$16 -> 420000 | D36: =Допущения!$D$16 -> 420000 | E36: =Допущения!$D$16 -> 420000 | F36: =Допущения!$D$16 -> 420000 | G36: =Допущения!$D$16 -> 420000 | H36: =Допущения!$D$16 -> 420000 | I36: =Допущения!$D$16 -> 420000 | J36: =Допущения!$D$16 -> 420000 | ... AL36: =Допущения!$D$16 -> 420000 | AM36: =SUM(C36:N36) -> 5040000 | AN36: =SUM(O36:Z36) -> 5040000 | AO36: =SUM(AA36:AL36) -> 5040000 | AP36: =SUM(C36:AL36) -> 15120000
A37: op | B37: Операционная прибыль (маржинальный доход − постоянные − привлечение) | C37: =C34-C36-C35 -> -420000 | D37: =D34-D36-D35 -> -420000 | E37: =E34-E36-E35 -> -446571.82 | F37: =F34-F36-F35 -> -457857.21 | G37: =G34-G36-G35 -> -462949.52 | H37: =H34-H36-H35 -> -466101.13 | I37: =I34-I36-I35 -> -468164.05 | J37: =J34-J36-J35 -> -469499.25 | ... AL37: =AL34-AL36-AL35 -> -398675.88 | AM37: =SUM(C37:N37) -> -5493349 | AN37: =SUM(O37:Z37) -> -5483958.2 | AO37: =SUM(AA37:AL37) -> -5019487.7 | AP37: =SUM(C37:AL37) -> -15996795
A38: capex | B38: CAPEX и вложения в оборотку | C38: =IF(C$24=1,Допущения!$D$18,0) -> 400000 | D38: =IF(D$24=1,Допущения!$D$18,0) -> 0 | E38: =IF(E$24=1,Допущения!$D$18,0) -> 0 | F38: =IF(F$24=1,Допущения!$D$18,0) -> 0 | G38: =IF(G$24=1,Допущения!$D$18,0) -> 0 | H38: =IF(H$24=1,Допущения!$D$18,0) -> 0 | I38: =IF(I$24=1,Допущения!$D$18,0) -> 0 | J38: =IF(J$24=1,Допущения!$D$18,0) -> 0 | ... AL38: =IF(AL$24=1,Допущения!$D$18,0) -> 0 | AM38: =SUM(C38:N38) -> 400000 | AN38: =SUM(O38:Z38) -> 0 | AO38: =SUM(AA38:AL38) -> 0 | AP38: =SUM(C38:AL38) -> 400000
A39: cf | B39: Денежный поток | C39: =C37-C38 -> -820000 | D39: =D37-D38 -> -420000 | E39: =E37-E38 -> -446571.82 | F39: =F37-F38 -> -457857.21 | G39: =G37-G38 -> -462949.52 | H39: =H37-H38 -> -466101.13 | I39: =I37-I38 -> -468164.05 | J39: =J37-J38 -> -469499.25 | ... AL39: =AL37-AL38 -> -398675.88 | AM39: =SUM(C39:N39) -> -5893349 | AN39: =SUM(O39:Z39) -> -5483958.2 | AO39: =SUM(AA39:AL39) -> -5019487.7 | AP39: =SUM(C39:AL39) -> -16396795
A40: cum | B40: Накопленный денежный поток | C40: =0+C39 -> -820000 | D40: =C40+D39 -> -1240000 | E40: =D40+E39 -> -1686571.8 | F40: =E40+F39 -> -2144429 | G40: =F40+G39 -> -2607378.5 | H40: =G40+H39 -> -3073479.7 | I40: =H40+I39 -> -3541643.7 | J40: =I40+J39 -> -4011143 | K40: =J40+K39 -> -4481443 | ... AL40: =AK40+AL39 -> -16396795 | AM40: =N40 -> -5893349 | AN40: =Z40 -> -11377307 | AO40: =AL40 -> -16396795
A41: be_flag | B41: служебно: месяц устойчивой опер. прибыли | C41: =IF(AND(C37>0,COUNTIF(C37:AL37,"<=0")=0),C$24,99) -> 99 | D41: =IF(AND(D37>0,COUNTIF(D37:AL37,"<=0")=0),D$24,99) -> 99 | E41: =IF(AND(E37>0,COUNTIF(E37:AL37,"<=0")=0),E$24,99) -> 99 | F41: =IF(AND(F37>0,COUNTIF(F37:AL37,"<=0")=0),F$24,99) -> 99 | G41: =IF(AND(G37>0,COUNTIF(G37:AL37,"<=0")=0),G$24,99) -> 99 | H41: =IF(AND(H37>0,COUNTIF(H37:AL37,"<=0")=0),H$24,99) -> 99 | I41: =IF(AND(I37>0,COUNTIF(I37:AL37,"<=0")=0),I$24,99) -> 99 | J41: =IF(AND(J37>0,COUNTIF(J37:AL37,"<=0")=0),J$24,99) -> 99 | K41: =IF(AND(K37>0,COUNTIF(K37:AL37,"<=0")=0),K$24,99) -> 99 | L41: =IF(AND(L37>0,COUNTIF(L37:AL37,"<=0")=0),L$24,99) -> 99 | M41: =IF(AND(M37>0,COUNTIF(M37:AL37,"<=0")=0),M$24,99) -> 99 | N41: =IF(AND(N37>0,COUNTIF(N37:AL37,"<=0")=0),N$24,99) -> 99 | O41: =IF(AND(O37>0,COUNTIF(O37:AL37,"<=0")=0),O$24,99) -> 99 | P41: =IF(AND(P37>0,COUNTIF(P37:AL37,"<=0")=0),P$24,99) -> 99 | Q41: =IF(AND(Q37>0,COUNTIF(Q37:AL37,"<=0")=0),Q$24,99) -> 99 | R41: =IF(AND(R37>0,COUNTIF(R37:AL37,"<=0")=0),R$24,99) -> 99 | S41: =IF(AND(S37>0,COUNTIF(S37:AL37,"<=0")=0),S$24,99) -> 99 | T41: =IF(AND(T37>0,COUNTIF(T37:AL37,"<=0")=0),T$24,99) -> 99 | U41: =IF(AND(U37>0,COUNTIF(U37:AL37,"<=0")=0),U$24,99) -> 99 | V41: =IF(AND(V37>0,COUNTIF(V37:AL37,"<=0")=0),V$24,99) -> 99 | W41: =IF(AND(W37>0,COUNTIF(W37:AL37,"<=0")=0),W$24,99) -> 99 | X41: =IF(AND(X37>0,COUNTIF(X37:AL37,"<=0")=0),X$24,99) -> 99 | Y41: =IF(AND(Y37>0,COUNTIF(Y37:AL37,"<=0")=0),Y$24,99) -> 99 | Z41: =IF(AND(Z37>0,COUNTIF(Z37:AL37,"<=0")=0),Z$24,99) -> 99 | AA41: =IF(AND(AA37>0,COUNTIF(AA37:AL37,"<=0")=0),AA$24,99) -> 99 | AB41: =IF(AND(AB37>0,COUNTIF(AB37:AL37,"<=0")=0),AB$24,99) -> 99 | AC41: =IF(AND(AC37>0,COUNTIF(AC37:AL37,"<=0")=0),AC$24,99) -> 99 | AD41: =IF(AND(AD37>0,COUNTIF(AD37:AL37,"<=0")=0),AD$24,99) -> 99 | AE41: =IF(AND(AE37>0,COUNTIF(AE37:AL37,"<=0")=0),AE$24,99) -> 99 | AF41: =IF(AND(AF37>0,COUNTIF(AF37:AL37,"<=0")=0),AF$24,99) -> 99 | AG41: =IF(AND(AG37>0,COUNTIF(AG37:AL37,"<=0")=0),AG$24,99) -> 99 | AH41: =IF(AND(AH37>0,COUNTIF(AH37:AL37,"<=0")=0),AH$24,99) -> 99 | AI41: =IF(AND(AI37>0,COUNTIF(AI37:AL37,"<=0")=0),AI$24,99) -> 99 | AJ41: =IF(AND(AJ37>0,COUNTIF(AJ37:AL37,"<=0")=0),AJ$24,99) -> 99 | AK41: =IF(AND(AK37>0,COUNTIF(AK37:AL37,"<=0")=0),AK$24,99) -> 99 | AL41: =IF(AND(AL37>0,COUNTIF(AL37:AL37,"<=0")=0),AL$24,99) -> 99
A42: pb_flag | B42: служебно: месяц окупаемости | C42: =IF(AND(C40>=0,COUNTIF(C40:AL40,"<0")=0),C$24,99) -> 99 | D42: =IF(AND(D40>=0,COUNTIF(D40:AL40,"<0")=0),D$24,99) -> 99 | E42: =IF(AND(E40>=0,COUNTIF(E40:AL40,"<0")=0),E$24,99) -> 99 | F42: =IF(AND(F40>=0,COUNTIF(F40:AL40,"<0")=0),F$24,99) -> 99 | G42: =IF(AND(G40>=0,COUNTIF(G40:AL40,"<0")=0),G$24,99) -> 99 | H42: =IF(AND(H40>=0,COUNTIF(H40:AL40,"<0")=0),H$24,99) -> 99 | I42: =IF(AND(I40>=0,COUNTIF(I40:AL40,"<0")=0),I$24,99) -> 99 | J42: =IF(AND(J40>=0,COUNTIF(J40:AL40,"<0")=0),J$24,99) -> 99 | K42: =IF(AND(K40>=0,COUNTIF(K40:AL40,"<0")=0),K$24,99) -> 99 | L42: =IF(AND(L40>=0,COUNTIF(L40:AL40,"<0")=0),L$24,99) -> 99 | M42: =IF(AND(M40>=0,COUNTIF(M40:AL40,"<0")=0),M$24,99) -> 99 | N42: =IF(AND(N40>=0,COUNTIF(N40:AL40,"<0")=0),N$24,99) -> 99 | O42: =IF(AND(O40>=0,COUNTIF(O40:AL40,"<0")=0),O$24,99) -> 99 | P42: =IF(AND(P40>=0,COUNTIF(P40:AL40,"<0")=0),P$24,99) -> 99 | Q42: =IF(AND(Q40>=0,COUNTIF(Q40:AL40,"<0")=0),Q$24,99) -> 99 | R42: =IF(AND(R40>=0,COUNTIF(R40:AL40,"<0")=0),R$24,99) -> 99 | S42: =IF(AND(S40>=0,COUNTIF(S40:AL40,"<0")=0),S$24,99) -> 99 | T42: =IF(AND(T40>=0,COUNTIF(T40:AL40,"<0")=0),T$24,99) -> 99 | U42: =IF(AND(U40>=0,COUNTIF(U40:AL40,"<0")=0),U$24,99) -> 99 | V42: =IF(AND(V40>=0,COUNTIF(V40:AL40,"<0")=0),V$24,99) -> 99 | W42: =IF(AND(W40>=0,COUNTIF(W40:AL40,"<0")=0),W$24,99) -> 99 | X42: =IF(AND(X40>=0,COUNTIF(X40:AL40,"<0")=0),X$24,99) -> 99 | Y42: =IF(AND(Y40>=0,COUNTIF(Y40:AL40,"<0")=0),Y$24,99) -> 99 | Z42: =IF(AND(Z40>=0,COUNTIF(Z40:AL40,"<0")=0),Z$24,99) -> 99 | AA42: =IF(AND(AA40>=0,COUNTIF(AA40:AL40,"<0")=0),AA$24,99) -> 99 | AB42: =IF(AND(AB40>=0,COUNTIF(AB40:AL40,"<0")=0),AB$24,99) -> 99 | AC42: =IF(AND(AC40>=0,COUNTIF(AC40:AL40,"<0")=0),AC$24,99) -> 99 | AD42: =IF(AND(AD40>=0,COUNTIF(AD40:AL40,"<0")=0),AD$24,99) -> 99 | AE42: =IF(AND(AE40>=0,COUNTIF(AE40:AL40,"<0")=0),AE$24,99) -> 99 | AF42: =IF(AND(AF40>=0,COUNTIF(AF40:AL40,"<0")=0),AF$24,99) -> 99 | AG42: =IF(AND(AG40>=0,COUNTIF(AG40:AL40,"<0")=0),AG$24,99) -> 99 | AH42: =IF(AND(AH40>=0,COUNTIF(AH40:AL40,"<0")=0),AH$24,99) -> 99 | AI42: =IF(AND(AI40>=0,COUNTIF(AI40:AL40,"<0")=0),AI$24,99) -> 99 | AJ42: =IF(AND(AJ40>=0,COUNTIF(AJ40:AL40,"<0")=0),AJ$24,99) -> 99 | AK42: =IF(AND(AK40>=0,COUNTIF(AK40:AL40,"<0")=0),AK$24,99) -> 99 | AL42: =IF(AND(AL40>=0,COUNTIF(AL40:AL40,"<0")=0),AL$24,99) -> 99
...

Sheet D_курсы_родителям
A1: D. Полный эскалатор + платные курсы и клуб для родителей (включает всю коммерцию A)
A4: Сценарий: Осторожный | B4: Месяц → | C4: 1 | D4: 2 | E4: 3 | F4: 4 | G4: 5 | H4: 6 | I4: 7 | J4: 8 | K4: 9 | L4: 10 | M4: 11 | N4: 12 | O4: 13 | P4: 14 | Q4: 15 | R4: 16 | S4: 17 | T4: 18 | U4: 19 | V4: 20 | W4: 21 | X4: 22 | Y4: 23 | Z4: 24 | AA4: 25 | AB4: 26 | AC4: 27 | AD4: 28 | AE4: 29 | AF4: 30 | AG4: 31 | AH4: 32 | AI4: 33 | AJ4: 34 | AK4: 35 | AL4: 36 | AM4: Год 1 | AN4: Год 2 | AO4: Год 3 | AP4: Итого 36 мес
A5: contribA | B5: Маржинальный доход A (коммерция, РСЯ, TG) | C5: =A_дропшиппинг!C14 -> 0 | D5: =A_дропшиппинг!D14 -> 0 | E5: =A_дропшиппинг!E14 -> 33.089139 | F5: =A_дропшиппинг!F14 -> 93.590218 | G5: =A_дропшиппинг!G14 -> 171.93621 | H5: =A_дропшиппинг!H14 -> 264.71311 | I5: =A_дропшиппинг!I14 -> 369.94782 | J5: =A_дропшиппинг!J14 -> 486.30904 | ... AL5: =A_дропшиппинг!AL14 -> 9041.6 | AM5: =SUM(C5:N5) -> 4720.9039 | AN5: =SUM(O5:Z5) -> 27051.945 | AO5: =SUM(AA5:AL5) -> 63228.025 | AP5: =SUM(C5:AL5) -> 95000.874
A6: warm | B6: Тёплая база (TG + email/VK) | C6: =A_дропшиппинг!C6*(1+Допущения!$C$34) -> 0 | D6: =A_дропшиппинг!D6*(1+Допущения!$C$34) -> 0 | E6: =A_дропшиппинг!E6*(1+Допущения!$C$34) -> 75.661141 | F6: =A_дропшиппинг!F6*(1+Допущения!$C$34) -> 214.00202 | G6: =A_дропшиппинг!G6*(1+Допущения!$C$34) -> 393.14682 | H6: =A_дропшиппинг!H6*(1+Допущения!$C$34) -> 605.28912 | I6: =A_дропшиппинг!I6*(1+Допущения!$C$34) -> 845.91727 | J6: =A_дропшиппинг!J6*(1+Допущения!$C$34) -> 1111.9871 | ... AL6: =A_дропшиппинг!AL6*(1+Допущения!$C$34) -> 15000 | AM6: =N6 -> 2392.6153 | AN6: =Z6 -> 7807.4085 | AO6: =AL6 -> 15000
A7: course | B7: Выручка курсов (сглажено по месяцам) | C7: =IF(C$4>=Допущения!$C$30,C6*Допущения!$C$33*Допущения!$C$31*Допущения!$C$32/12,0) -> 0 | D7: =IF(D$4>=Допущения!$C$30,D6*Допущения!$C$33*Допущения!$C$31*Допущения!$C$32/12,0) -> 0 | E7: =IF(E$4>=Допущения!$C$30,E6*Допущения!$C$33*Допущения!$C$31*Допущения!$C$32/12,0) -> 0 | F7: =IF(F$4>=Допущения!$C$30,F6*Допущения!$C$33*Допущения!$C$31*Допущения!$C$32/12,0) -> 0 | G7: =IF(G$4>=Допущения!$C$30,G6*Допущения!$C$33*Допущения!$C$31*Допущения!$C$32/12,0) -> 0 | H7: =IF(H$4>=Допущения!$C$30,H6*Допущения!$C$33*Допущения!$C$31*Допущения!$C$32/12,0) -> 0 | I7: =IF(I$4>=Допущения!$C$30,I6*Допущения!$C$33*Допущения!$C$31*Допущения!$C$32/12,0) -> 0 | J7: =IF(J$4>=Допущения!$C$30,J6*Допущения!$C$33*Допущения!$C$31*Допущения!$C$32/12,0) -> 0 | ... AL7: =IF(AL$4>=Допущения!$C$30,AL6*Допущения!$C$33*Допущения!$C$31*Допущения!$C$32/12,0) -> 19000 | AM7: =SUM(C7:N7) -> 3030.6461 | AN7: =SUM(O7:Z7) -> 78351.671 | AO7: =SUM(AA7:AL7) -> 175942.39 | AP7: =SUM(C7:AL7) -> 257324.71
A8: club | B8: Выручка клуба | C8: =IF(C$4>=Допущения!$C$30,C6*Допущения!$C$36*Допущения!$C$35,0) -> 0 | D8: =IF(D$4>=Допущения!$C$30,D6*Допущения!$C$36*Допущения!$C$35,0) -> 0 | E8: =IF(E$4>=Допущения!$C$30,E6*Допущения!$C$36*Допущения!$C$35,0) -> 0 | F8: =IF(F$4>=Допущения!$C$30,F6*Допущения!$C$36*Допущения!$C$35,0) -> 0 | G8: =IF(G$4>=Допущения!$C$30,G6*Допущения!$C$36*Допущения!$C$35,0) -> 0 | H8: =IF(H$4>=Допущения!$C$30,H6*Допущения!$C$36*Допущения!$C$35,0) -> 0 | I8: =IF(I$4>=Допущения!$C$30,I6*Допущения!$C$36*Допущения!$C$35,0) -> 0 | J8: =IF(J$4>=Допущения!$C$30,J6*Допущения!$C$36*Допущения!$C$35,0) -> 0 | ... AL8: =IF(AL$4>=Допущения!$C$30,AL6*Допущения!$C$36*Допущения!$C$35,0) -> 13050 | AM8: =SUM(C8:N8) -> 2081.5753 | AN8: =SUM(O8:Z8) -> 53815.226 | AO8: =SUM(AA8:AL8) -> 120844.64 | AP8: =SUM(C8:AL8) -> 176741.44
A9: rev | B9: Выручка платных продуктов | C9: =C7+C8 -> 0 | D9: =D7+D8 -> 0 | E9: =E7+E8 -> 0 | F9: =F7+F8 -> 0 | G9: =G7+G8 -> 0 | H9: =H7+H8 -> 0 | I9: =I7+I8 -> 0 | J9: =J7+J8 -> 0 | ... AL9: =AL7+AL8 -> 32050 | AM9: =SUM(C9:N9) -> 5112.2215 | AN9: =SUM(O9:Z9) -> 132166.9 | AO9: =SUM(AA9:AL9) -> 296787.03 | AP9: =SUM(C9:AL9) -> 434066.15
A10: contrib | B10: Маржинальный доход (A + продукты − комиссии, реклама запусков, налог) | C10: =C5+C9*(1-Допущения!$C$37-Допущения!$C$14)-C7*Допущения!$C$38 -> 0 | D10: =D5+D9*(1-Допущения!$C$37-Допущения!$C$14)-D7*Допущения!$C$38 -> 0 | E10: =E5+E9*(1-Допущения!$C$37-Допущения!$C$14)-E7*Допущения!$C$38 -> 33.089139 | F10: =F5+F9*(1-Допущения!$C$37-Допущения!$C$14)-F7*Допущения!$C$38 -> 93.590218 | G10: =G5+G9*(1-Допущения!$C$37-Допущения!$C$14)-G7*Допущения!$C$38 -> 171.93621 | H10: =H5+H9*(1-Допущения!$C$37-Допущения!$C$14)-H7*Допущения!$C$38 -> 264.71311 | I10: =I5+I9*(1-Допущения!$C$37-Допущения!$C$14)-I7*Допущения!$C$38 -> 369.94782 | J10: =J5+J9*(1-Допущения!$C$37-Допущения!$C$14)-J7*Допущения!$C$38 -> 486.30904 | ... AL10: =AL5+AL9*(1-Допущения!$C$37-Допущения!$C$14)-AL7*Допущения!$C$38 -> 30572.6 | AM10: =SUM(C10:N10) -> 8155.264 | AN10: =SUM(O10:Z10) -> 115840.88 | AO10: =SUM(AA10:AL10) -> 262607.79 | AP10: =SUM(C10:AL10) -> 386603.94
A11: acq | B11: Покупка подписчиков Telegram | C11: =A_дропшиппинг!C15 -> 0 | D11: =A_дропшиппинг!D15 -> 0 | E11: =A_дропшиппинг!E15 -> 12105.782 | F11: =A_дропшиппинг!F15 -> 22134.541 | G11: =A_дропшиппинг!G15 -> 28663.167 | H11: =A_дропшиппинг!H15 -> 33942.769 | I11: =A_дропшиппинг!I15 -> 38500.503 | J11: =A_дропшиппинг!J15 -> 42571.177 | ... AL11: =A_дропшиппинг!AL15 -> 105099.95 | AM11: =SUM(C11:N11) -> 382818.45 | AN11: =SUM(O11:Z11) -> 866366.91 | AO11: =SUM(AA11:AL11) -> 1150814.6 | AP11: =SUM(C11:AL11) -> 2400000
A12: fixed | B12: Постоянные расходы (команда) | C12: =Допущения!$C$16+IF(C$4>=Допущения!$C$30-1,Допущения!$C$39,0) -> 480000 | D12: =Допущения!$C$16+IF(D$4>=Допущения!$C$30-1,Допущения!$C$39,0) -> 480000 | E12: =Допущения!$C$16+IF(E$4>=Допущения!$C$30-1,Допущения!$C$39,0) -> 480000 | F12: =Допущения!$C$16+IF(F$4>=Допущения!$C$30-1,Допущения!$C$39,0) -> 480000 | G12: =Допущения!$C$16+IF(G$4>=Допущения!$C$30-1,Допущения!$C$39,0) -> 480000 | H12: =Допущения!$C$16+IF(H$4>=Допущения!$C$30-1,Допущения!$C$39,0) -> 480000 | I12: =Допущения!$C$16+IF(I$4>=Допущения!$C$30-1,Допущения!$C$39,0) -> 480000 | J12: =Допущения!$C$16+IF(J$4>=Допущения!$C$30-1,Допущения!$C$39,0) -> 480000 | ... AL12: =Допущения!$C$16+IF(AL$4>=Допущения!$C$30-1,Допущения!$C$39,0) -> 600000 | AM12: =SUM(C12:N12) -> 6000000 | AN12: =SUM(O12:Z12) -> 7200000 | AO12: =SUM(AA12:AL12) -> 7200000 | AP12: =SUM(C12:AL12) -> 20400000
A13: op | B13: Операционная прибыль (маржинальный доход − постоянные − привлечение) | C13: =C10-C12-C11 -> -480000 | D13: =D10-D12-D11 -> -480000 | E13: =E10-E12-E11 -> -492072.69 | F13: =F10-F12-F11 -> -502040.95 | G13: =G10-G12-G11 -> -508491.23 | H13: =H10-H12-H11 -> -513678.06 | I13: =I10-I12-I11 -> -518130.56 | J13: =J10-J12-J11 -> -522084.87 | ... AL13: =AL10-AL12-AL11 -> -674527.35 | AM13: =SUM(C13:N13) -> -6374663.2 | AN13: =SUM(O13:Z13) -> -7950526 | AO13: =SUM(AA13:AL13) -> -8088206.8 | AP13: =SUM(C13:AL13) -> -22413396
A14: capex | B14: CAPEX и вложения в оборотку | C14: =IF(C$4=1,Допущения!$C$18,0)+IF(AND(C$4>=Допущения!$C$30-3,C$4<Допущения!$C$30),Допущения!$C$40/3,0) -> 600000 | D14: =IF(D$4=1,Допущения!$C$18,0)+IF(AND(D$4>=Допущения!$C$30-3,D$4<Допущения!$C$30),Допущения!$C$40/3,0) -> 0 | E14: =IF(E$4=1,Допущения!$C$18,0)+IF(AND(E$4>=Допущения!$C$30-3,E$4<Допущения!$C$30),Допущения!$C$40/3,0) -> 0 | F14: =IF(F$4=1,Допущения!$C$18,0)+IF(AND(F$4>=Допущения!$C$30-3,F$4<Допущения!$C$30),Допущения!$C$40/3,0) -> 0 | G14: =IF(G$4=1,Допущения!$C$18,0)+IF(AND(G$4>=Допущения!$C$30-3,G$4<Допущения!$C$30),Допущения!$C$40/3,0) -> 0 | H14: =IF(H$4=1,Допущения!$C$18,0)+IF(AND(H$4>=Допущения!$C$30-3,H$4<Допущения!$C$30),Допущения!$C$40/3,0) -> 0 | I14: =IF(I$4=1,Допущения!$C$18,0)+IF(AND(I$4>=Допущения!$C$30-3,I$4<Допущения!$C$30),Допущения!$C$40/3,0) -> 0 | J14: =IF(J$4=1,Допущения!$C$18,0)+IF(AND(J$4>=Допущения!$C$30-3,J$4<Допущения!$C$30),Допущения!$C$40/3,0) -> 0 | ... AL14: =IF(AL$4=1,Допущения!$C$18,0)+IF(AND(AL$4>=Допущения!$C$30-3,AL$4<Допущения!$C$30),Допущения!$C$40/3,0) -> 0 | AM14: =SUM(C14:N14) -> 1800000 | AN14: =SUM(O14:Z14) -> 0 | AO14: =SUM(AA14:AL14) -> 0 | AP14: =SUM(C14:AL14) -> 1800000
A15: cf | B15: Денежный поток | C15: =C13-C14 -> -1080000 | D15: =D13-D14 -> -480000 | E15: =E13-E14 -> -492072.69 | F15: =F13-F14 -> -502040.95 | G15: =G13-G14 -> -508491.23 | H15: =H13-H14 -> -513678.06 | I15: =I13-I14 -> -518130.56 | J15: =J13-J14 -> -522084.87 | ... AL15: =AL13-AL14 -> -674527.35 | AM15: =SUM(C15:N15) -> -8174663.2 | AN15: =SUM(O15:Z15) -> -7950526 | AO15: =SUM(AA15:AL15) -> -8088206.8 | AP15: =SUM(C15:AL15) -> -24213396
A16: cum | B16: Накопленный денежный поток | C16: =0+C15 -> -1080000 | D16: =C16+D15 -> -1560000 | E16: =D16+E15 -> -2052072.7 | F16: =E16+F15 -> -2554113.6 | G16: =F16+G15 -> -3062604.9 | H16: =G16+H15 -> -3576282.9 | I16: =H16+I15 -> -4094413.5 | J16: =I16+J15 -> -4616498.4 | K16: =J16+K15 -> -5542169.8 | ... AL16: =AK16+AL15 -> -24213396 | AM16: =N16 -> -8174663.2 | AN16: =Z16 -> -16125189 | AO16: =AL16 -> -24213396
