Workbook

Sheet README
A1: Proba Lab — сценарная финансовая модель 2026–2029 (36 мес.)
A2: Жёлтые ячейки на листе «Допущения» и «Объёмы» — изменяемые предположения. Остальное считается формулами.
A3: Это целевые сценарии бюро, а НЕ рыночный прогноз. Цены — оценка на основе трудоёмкости, подлежит проверке на первых 10 переговорах.
A4: Налоги: упрощённо ИП на УСН «доходы» 6% + 1% взносов с дохода свыше 300 тыс./год (≈25 тыс./мес.) + фиксированные взносы ≈4,8 тыс./мес.
A5: Уменьшение налога на сумму взносов (разрешено ИП) НЕ учтено — модель консервативна. Сверьте режим с бухгалтером.
A6: НДС: если выручка предыдущего года > порога (20 млн ₽ в 2026–2029 по закону 228-ФЗ — проверить), применяется ставка 5% без вычетов.
A7: Личный доход основателя = прибыль после налогов × доля изъятия. Для ООО добавьте НДФЛ с дивидендов (13–15%).
A8: Часы основателя — ключевой ограничитель. Если «Часы основателя/нед.» > 15, сценарий нереализуем без найма или ухода с основной работы.
A9: Листы: Допущения → Объёмы (по периодам и сценариям) → Консерв./Базовый/Оптим. (помесячно) → Сводка.

Sheet Допущения
A1: Параметр | B1: Значение | C1: Комментарий
A2: Цена: аудит доказательности (Entry), ₽ | B2: 90000 | C2: диапазон 60–120 тыс.
A3: Цена: core-проект (досье/GTM), средняя, ₽ | B3: 420000 | C3: досье 380 тыс., GTM 450 тыс., пакет 690 тыс.
A4: Цена: абонемент «внешний продуктовый офис», ₽/мес | B4: 140000 | C4: мин. срок 3 мес.
A5: Себестоимость аудита, % выручки | B5: 0.2 | C5: аналитик + дизайн
A6: Себестоимость core-проекта, % выручки | B6: 0.35 | C6: медрайтер, дизайн, юрист по рекламе
A7: Себестоимость абонемента, % выручки | B7: 0.4 | C7: аналитик/райтер, дизайн
A8: Индексация цен, год 2 | B8: 1.1
A9: Индексация цен, год 3 | B9: 1.2 | C9: к уровню года 1
A10: Opex/мес, период 1 (м1–3), ₽ | B10: 35000 | C10: CRM, сервисы, бухгалтерия, домен, юрист
A11: Opex/мес, период 2 (м4–6), ₽ | B11: 35000
A12: Opex/мес, период 3 (м7–12), ₽ | B12: 45000 | C12: + конференции
A13: Opex/мес, период 4 (м13–24), ₽ | B13: 70000
A14: Opex/мес, период 5 (м25–36), ₽ | B14: 90000
A15: Стоимость 1 штатного FTE (руководитель проектов/медрайтер), ₽/мес | B15: 170000 | C15: с взносами
A16: Ставка УСН | B16: 0.06
A17: Доп. взносы ИП с дохода > 300 тыс./год | B17: 0.01
A18: Порог дохода, ₽/мес, выше которого 1% | B18: 25000 | C18: 300 тыс./12
A19: Фикс. взносы ИП, ₽/мес | B19: 4800 | C19: ≈57,4 тыс./год (2026) — проверить
A20: Порог НДС, ₽/год | B20: 20000000
A21: Ставка НДС (спецставка без вычетов) | B21: 0.05
A22: Доля изъятия прибыли основателем | B22: 0.7 | C22: остальное — резерв/развитие
A23: Часы основателя: аудит, ч | B23: 10 | C23: после стандартизации; первые 3 — 14 ч
A24: Часы основателя: core-проект, ч | B24: 30
A25: Часы основателя: абонемент, ч/мес | B25: 8
A26: Часы основателя: продажи и админ., ч/мес | B26: 16
A27: Снижение часов основателя на 1 FTE, ч/мес | B27: 40

Sheet Сводка
A1: Сценарий | B1: Горизонт | C1: Выручка | D1: Себестоимость | E1: Opex | F1: Налоги (УСН+взносы+НДС) | G1: Прибыль бизнеса | H1: Личный доход основателя | I1: Ср. часы основателя/нед
A2: Консерв. | B2: 3 мес | C2: =SUM('Консерв.'!H2:H4) -> 89100 | D2: =SUM('Консерв.'!I2:I4) -> 17820 | E2: =SUM('Консерв.'!K2:K4) -> 105000 | F2: =SUM('Консерв.'!L2:L4)+SUM('Консерв.'!M2:M4) -> 19887 | G2: =SUM('Консерв.'!N2:N4) -> -53607 | H2: =SUM('Консерв.'!O2:O4) -> 0 | I2: =AVERAGE('Консерв.'!Q2:Q4) -> 4.4572748
A3: Консерв. | B3: 6 мес | C3: =SUM('Консерв.'!H2:H7) -> 685800 | D3: =SUM('Консерв.'!I2:I7) -> 199530 | E3: =SUM('Консерв.'!K2:K7) -> 210000 | F3: =SUM('Консерв.'!L2:L7)+SUM('Консерв.'!M2:M7) -> 75306 | G3: =SUM('Консерв.'!N2:N7) -> 200964 | H3: =SUM('Консерв.'!O2:O7) -> 178199.7 | I3: =AVERAGE('Консерв.'!Q2:Q7) -> 5.9930716
A4: Консерв. | B4: 12 мес | C4: =SUM('Консерв.'!H2:H13) -> 2897400 | D4: =SUM('Консерв.'!I2:I13) -> 934590 | E4: =SUM('Консерв.'!K2:K13) -> 480000 | F4: =SUM('Консерв.'!L2:L13)+SUM('Консерв.'!M2:M13) -> 257418 | G4: =SUM('Консерв.'!N2:N13) -> 1225392 | H4: =SUM('Консерв.'!O2:O13) -> 895299.3 | I4: =AVERAGE('Консерв.'!Q2:Q13) -> 8.0658199
A5: Консерв. | B5: Год 2 (м13–24) | C5: =SUM('Консерв.'!H14:H25) -> 8250000 | D5: =SUM('Консерв.'!I14:I25) -> 2805000 | E5: =SUM('Консерв.'!K14:K25) -> 840000 | F5: =SUM('Консерв.'!L14:L25)+SUM('Консерв.'!M14:M25) -> 632100 | G5: =SUM('Консерв.'!N14:N25) -> 3972900 | H5: =SUM('Консерв.'!O14:O25) -> 2781030 | I5: =AVERAGE('Консерв.'!Q14:Q25) -> 14.318707
A6: Консерв. | B6: Год 3 (м25–36) | C6: =SUM('Консерв.'!H26:H37) -> 13176000 | D6: =SUM('Консерв.'!I26:I37) -> 4525200 | E6: =SUM('Консерв.'!K26:K37) -> 3120000 | F6: =SUM('Консерв.'!L26:L37)+SUM('Консерв.'!M26:M37) -> 976920 | G6: =SUM('Консерв.'!N26:N37) -> 4553880 | H6: =SUM('Консерв.'!O26:O37) -> 3187716 | I6: =AVERAGE('Консерв.'!Q26:Q37) -> 9.8152425
A7: Консерв. | B7: 36 мес итого | C7: =SUM('Консерв.'!H2:H37) -> 24323400 | D7: =SUM('Консерв.'!I2:I37) -> 8264790 | E7: =SUM('Консерв.'!K2:K37) -> 4440000 | F7: =SUM('Консерв.'!L2:L37)+SUM('Консерв.'!M2:M37) -> 1866438 | G7: =SUM('Консерв.'!N2:N37) -> 9752172 | H7: =SUM('Консерв.'!O2:O37) -> 6864045.3 | I7: =AVERAGE('Консерв.'!Q2:Q37) -> 10.733256
A9: Базовый | B9: 3 мес | C9: =SUM(Базовый!H2:H4) -> 180900 | D9: =SUM(Базовый!I2:I4) -> 36180 | E9: =SUM(Базовый!K2:K4) -> 105000 | F9: =SUM(Базовый!L2:L4)+SUM(Базовый!M2:M4) -> 26313 | G9: =SUM(Базовый!N2:N4) -> 13407 | H9: =SUM(Базовый!O2:O4) -> 9384.9 | I9: =AVERAGE(Базовый!Q2:Q4) -> 5.2424942
A10: Базовый | B10: 6 мес | C10: =SUM(Базовый!H2:H7) -> 1500900 | D10: =SUM(Базовый!I2:I7) -> 478680 | E10: =SUM(Базовый!K2:K7) -> 210000 | F10: =SUM(Базовый!L2:L7)+SUM(Базовый!M2:M7) -> 132363 | G10: =SUM(Базовый!N2:N7) -> 679857 | H10: =SUM(Базовый!O2:O7) -> 475899.9 | I10: =AVERAGE(Базовый!Q2:Q7) -> 8.2794457
A11: Базовый | B11: 12 мес | C11: =SUM(Базовый!H2:H13) -> 4980900 | D11: =SUM(Базовый!I2:I13) -> 1699680 | E11: =SUM(Базовый!K2:K13) -> 480000 | F11: =SUM(Базовый!L2:L13)+SUM(Базовый!M2:M13) -> 403263 | G11: =SUM(Базовый!N2:N13) -> 2397957 | H11: =SUM(Базовый!O2:O13) -> 1678569.9 | I11: =AVERAGE(Базовый!Q2:Q13) -> 10.721709
A12: Базовый | B12: Год 2 (м13–24) | C12: =SUM(Базовый!H14:H25) -> 15312000 | D12: =SUM(Базовый!I14:I25) -> 5372400 | E12: =SUM(Базовый!K14:K25) -> 2880000 | F12: =SUM(Базовый!L14:L25)+SUM(Базовый!M14:M25) -> 1126440 | G12: =SUM(Базовый!N14:N25) -> 5933160 | H12: =SUM(Базовый!O14:O25) -> 4153212 | I12: =AVERAGE(Базовый!Q14:Q25) -> 13.394919
A13: Базовый | B13: Год 3 (м25–36) | C13: =SUM(Базовый!H26:H37) -> 25056000 | D13: =SUM(Базовый!I26:I37) -> 8791200 | E13: =SUM(Базовый!K26:K37) -> 5160000 | F13: =SUM(Базовый!L26:L37)+SUM(Базовый!M26:M37) -> 1808520 | G13: =SUM(Базовый!N26:N37) -> 9296280 | H13: =SUM(Базовый!O26:O37) -> 6507396 | I13: =AVERAGE(Базовый!Q26:Q37) -> 13.625866
A14: Базовый | B14: 36 мес итого | C14: =SUM(Базовый!H2:H37) -> 45348900 | D14: =SUM(Базовый!I2:I37) -> 15863280 | E14: =SUM(Базовый!K2:K37) -> 8520000 | F14: =SUM(Базовый!L2:L37)+SUM(Базовый!M2:M37) -> 3338223 | G14: =SUM(Базовый!N2:N37) -> 17627397 | H14: =SUM(Базовый!O2:O37) -> 12339178 | I14: =AVERAGE(Базовый!Q2:Q37) -> 12.580831
A16: Оптим. | B16: 3 мес | C16: =SUM('Оптим.'!H2:H4) -> 685800 | D16: =SUM('Оптим.'!I2:I4) -> 199530 | E16: =SUM('Оптим.'!K2:K4) -> 105000 | F16: =SUM('Оптим.'!L2:L4)+SUM('Оптим.'!M2:M4) -> 61656 | G16: =SUM('Оптим.'!N2:N4) -> 319614 | H16: =SUM('Оптим.'!O2:O4) -> 223729.8 | I16: =AVERAGE('Оптим.'!Q2:Q4) -> 8.2909931
A17: Оптим. | B17: 6 мес | C17: =SUM('Оптим.'!H2:H7) -> 2355000 | D17: =SUM('Оптим.'!I2:I7) -> 744000 | E17: =SUM('Оптим.'!K2:K7) -> 210000 | F17: =SUM('Оптим.'!L2:L7)+SUM('Оптим.'!M2:M7) -> 192150 | G17: =SUM('Оптим.'!N2:N7) -> 1208850 | H17: =SUM('Оптим.'!O2:O7) -> 846195 | I17: =AVERAGE('Оптим.'!Q2:Q7) -> 10.969977
A18: Оптим. | B18: 12 мес | C18: =SUM('Оптим.'!H2:H13) -> 8475000 | D18: =SUM('Оптим.'!I2:I13) -> 2850000 | E18: =SUM('Оптим.'!K2:K13) -> 1500000 | F18: =SUM('Оптим.'!L2:L13)+SUM('Оптим.'!M2:M13) -> 647850 | G18: =SUM('Оптим.'!N2:N13) -> 3477150 | H18: =SUM('Оптим.'!O2:O13) -> 2434005 | I18: =AVERAGE('Оптим.'!Q2:Q13) -> 11.258661
A19: Оптим. | B19: Год 2 (м13–24) | C19: =SUM('Оптим.'!H14:H25) -> 22968000 | D19: =SUM('Оптим.'!I14:I25) -> 8058600 | E19: =SUM('Оптим.'!K14:K25) -> 4920000 | F19: =SUM('Оптим.'!L14:L25)+SUM('Оптим.'!M14:M25) -> 1662360 | G19: =SUM('Оптим.'!N14:N25) -> 8327040 | H19: =SUM('Оптим.'!O14:O25) -> 5828928 | I19: =AVERAGE('Оптим.'!Q14:Q25) -> 13.625866
A20: Оптим. | B20: Год 3 (м25–36) | C20: =SUM('Оптим.'!H26:H37) -> 38448000 | D20: =SUM('Оптим.'!I26:I37) -> 13586400 | E20: =SUM('Оптим.'!K26:K37) -> 7200000 | F20: =SUM('Оптим.'!L26:L37)+SUM('Оптим.'!M26:M37) -> 4533792 | G20: =SUM('Оптим.'!N26:N37) -> 13127808 | H20: =SUM('Оптим.'!O26:O37) -> 9189465.6 | I20: =AVERAGE('Оптим.'!Q26:Q37) -> 19.168591
A21: Оптим. | B21: 36 мес итого | C21: =SUM('Оптим.'!H2:H37) -> 69891000 | D21: =SUM('Оптим.'!I2:I37) -> 24495000 | E21: =SUM('Оптим.'!K2:K37) -> 13620000 | F21: =SUM('Оптим.'!L2:L37)+SUM('Оптим.'!M2:M37) -> 6844002 | G21: =SUM('Оптим.'!N2:N37) -> 24931998 | H21: =SUM('Оптим.'!O2:O37) -> 17452399 | I21: =AVERAGE('Оптим.'!Q2:Q37) -> 14.684373

Sheet Объёмы
A1: Сценарий / показатель | B1: м1–3 | C1: м4–6 | D1: м7–12 | E1: м13–24 | F1: м25–36
A2: Консерв.
A3: аудитов в месяц | B3: 0.33 | C3: 0.67 | D3: 1 | E3: 1.5 | F3: 2
A4: core-проектов в месяц | B4: 0 | C4: 0.33 | D4: 0.33 | E4: 0.5 | F4: 0.75
A5: активных абонементов | B5: 0 | C5: 0 | D5: 1 | E5: 2 | F5: 3
A6: штатных FTE | B6: 0 | C6: 0 | D6: 0 | E6: 0 | F6: 1
A7: Базовый
A8: аудитов в месяц | B8: 0.67 | C8: 1 | D8: 1 | E8: 2 | F8: 3
A9: core-проектов в месяц | B9: 0 | C9: 0.5 | D9: 0.5 | E9: 1 | F9: 1.5
A10: активных абонементов | B10: 0 | C10: 1 | D10: 2 | E10: 4 | F10: 6
A11: штатных FTE | B11: 0 | C11: 0 | D11: 0 | E11: 1 | F11: 2
A12: Оптим.
A13: аудитов в месяц | B13: 1 | C13: 1.5 | D13: 2 | E13: 3 | F13: 4
A14: core-проектов в месяц | B14: 0.33 | C14: 0.67 | D14: 1 | E14: 1.5 | F14: 2.5
A15: активных абонементов | B15: 0 | C15: 1 | D15: 3 | E15: 6 | F15: 9
A16: штатных FTE | B16: 0 | C16: 0 | D16: 1 | E16: 2 | F16: 3

Sheet Консерв.
A1: Месяц | B1: Год | C1: Период | D1: Аудиты | E1: Core | F1: Абонементы | G1: FTE | H1: Выручка | I1: Себестоимость | J1: Валовая прибыль | K1: Opex (вкл. FTE) | L1: НДС | M1: УСН+взносы | N1: Прибыль после налогов | O1: Изъятие основателя | P1: Часы основателя/мес | Q1: Часы основателя/нед | R1: Выручка за год до
A2: 1 | B2: =INT((A2-1)/12)+1 -> 1 | C2: =IF(A2<=3,1,IF(A2<=6,2,IF(A2<=12,3,IF(A2<=24,4,5)))) -> 1 | D2: =INDEX(Объёмы!$B$3:$F$3,C2) -> 0.33 | E2: =INDEX(Объёмы!$B$4:$F$4,C2) -> 0 | F2: =INDEX(Объёмы!$B$5:$F$5,C2) -> 0 | G2: =INDEX(Объёмы!$B$6:$F$6,C2) -> 0 | H2: =(D2*Допущения!$B$2+E2*Допущения!$B$3+F2*Допущения!$B$4)*IF(B2=1,1,IF(B2=2,Допущения!$B$8,Допущения!$B$9)) -> 29700 | I2: =(D2*Допущения!$B$2*Допущения!$B$5+E2*Допущения!$B$3*Допущения!$B$6+F2*Допущения!$B$4*Допущения!$B$7)*IF(B2=1,1,IF(B2=2,Допущения!$B$8,Допущения!$B$9)) -> 5940 | J2: =H2-I2 -> 23760 | K2: =INDEX(Допущения!$B$10:$B$14, C2)+G2*Допущения!$B$15 -> 35000 | L2: =IF(R2>Допущения!$B$20,H2*Допущения!$B$21,0) -> 0 | M2: =(H2-L2)*Допущения!$B$16+MAX(0,H2-L2-Допущения!$B$18)*Допущения!$B$17+Допущения!$B$19 -> 6629 | N2: =J2-K2-L2-M2 -> -17869 | O2: =MAX(0,N2)*Допущения!$B$22 -> 0 | P2: =MAX(0,D2*Допущения!$B$23+E2*Допущения!$B$24+F2*Допущения!$B$25-G2*Допущения!$B$27)+Допущения!$B$26 -> 19.3 | Q2: =P2/4.33 -> 4.4572748 | R2: 0
A3: 2 | B3: =INT((A3-1)/12)+1 -> 1 | C3: =IF(A3<=3,1,IF(A3<=6,2,IF(A3<=12,3,IF(A3<=24,4,5)))) -> 1 | D3: =INDEX(Объёмы!$B$3:$F$3,C3) -> 0.33 | E3: =INDEX(Объёмы!$B$4:$F$4,C3) -> 0 | F3: =INDEX(Объёмы!$B$5:$F$5,C3) -> 0 | G3: =INDEX(Объёмы!$B$6:$F$6,C3) -> 0 | H3: =(D3*Допущения!$B$2+E3*Допущения!$B$3+F3*Допущения!$B$4)*IF(B3=1,1,IF(B3=2,Допущения!$B$8,Допущения!$B$9)) -> 29700 | I3: =(D3*Допущения!$B$2*Допущения!$B$5+E3*Допущения!$B$3*Допущения!$B$6+F3*Допущения!$B$4*Допущения!$B$7)*IF(B3=1,1,IF(B3=2,Допущения!$B$8,Допущения!$B$9)) -> 5940 | J3: =H3-I3 -> 23760 | K3: =INDEX(Допущения!$B$10:$B$14, C3)+G3*Допущения!$B$15 -> 35000 | L3: =IF(R3>Допущения!$B$20,H3*Допущения!$B$21,0) -> 0 | M3: =(H3-L3)*Допущения!$B$16+MAX(0,H3-L3-Допущения!$B$18)*Допущения!$B$17+Допущения!$B$19 -> 6629 | N3: =J3-K3-L3-M3 -> -17869 | O3: =MAX(0,N3)*Допущения!$B$22 -> 0 | P3: =MAX(0,D3*Допущения!$B$23+E3*Допущения!$B$24+F3*Допущения!$B$25-G3*Допущения!$B$27)+Допущения!$B$26 -> 19.3 | Q3: =P3/4.33 -> 4.4572748 | R3: 0
A4: 3 | B4: =INT((A4-1)/12)+1 -> 1 | C4: =IF(A4<=3,1,IF(A4<=6,2,IF(A4<=12,3,IF(A4<=24,4,5)))) -> 1 | D4: =INDEX(Объёмы!$B$3:$F$3,C4) -> 0.33 | E4: =INDEX(Объёмы!$B$4:$F$4,C4) -> 0 | F4: =INDEX(Объёмы!$B$5:$F$5,C4) -> 0 | G4: =INDEX(Объёмы!$B$6:$F$6,C4) -> 0 | H4: =(D4*Допущения!$B$2+E4*Допущения!$B$3+F4*Допущения!$B$4)*IF(B4=1,1,IF(B4=2,Допущения!$B$8,Допущения!$B$9)) -> 29700 | I4: =(D4*Допущения!$B$2*Допущения!$B$5+E4*Допущения!$B$3*Допущения!$B$6+F4*Допущения!$B$4*Допущения!$B$7)*IF(B4=1,1,IF(B4=2,Допущения!$B$8,Допущения!$B$9)) -> 5940 | J4: =H4-I4 -> 23760 | K4: =INDEX(Допущения!$B$10:$B$14, C4)+G4*Допущения!$B$15 -> 35000 | L4: =IF(R4>Допущения!$B$20,H4*Допущения!$B$21,0) -> 0 | M4: =(H4-L4)*Допущения!$B$16+MAX(0,H4-L4-Допущения!$B$18)*Допущения!$B$17+Допущения!$B$19 -> 6629 | N4: =J4-K4-L4-M4 -> -17869 | O4: =MAX(0,N4)*Допущения!$B$22 -> 0 | P4: =MAX(0,D4*Допущения!$B$23+E4*Допущения!$B$24+F4*Допущения!$B$25-G4*Допущения!$B$27)+Допущения!$B$26 -> 19.3 | Q4: =P4/4.33 -> 4.4572748 | R4: 0
A5: 4 | B5: =INT((A5-1)/12)+1 -> 1 | C5: =IF(A5<=3,1,IF(A5<=6,2,IF(A5<=12,3,IF(A5<=24,4,5)))) -> 2 | D5: =INDEX(Объёмы!$B$3:$F$3,C5) -> 0.67 | E5: =INDEX(Объёмы!$B$4:$F$4,C5) -> 0.33 | F5: =INDEX(Объёмы!$B$5:$F$5,C5) -> 0 | G5: =INDEX(Объёмы!$B$6:$F$6,C5) -> 0 | H5: =(D5*Допущения!$B$2+E5*Допущения!$B$3+F5*Допущения!$B$4)*IF(B5=1,1,IF(B5=2,Допущения!$B$8,Допущения!$B$9)) -> 198900 | I5: =(D5*Допущения!$B$2*Допущения!$B$5+E5*Допущения!$B$3*Допущения!$B$6+F5*Допущения!$B$4*Допущения!$B$7)*IF(B5=1,1,IF(B5=2,Допущения!$B$8,Допущения!$B$9)) -> 60570 | J5: =H5-I5 -> 138330 | K5: =INDEX(Допущения!$B$10:$B$14, C5)+G5*Допущения!$B$15 -> 35000 | L5: =IF(R5>Допущения!$B$20,H5*Допущения!$B$21,0) -> 0 | M5: =(H5-L5)*Допущения!$B$16+MAX(0,H5-L5-Допущения!$B$18)*Допущения!$B$17+Допущения!$B$19 -> 18473 | N5: =J5-K5-L5-M5 -> 84857 | O5: =MAX(0,N5)*Допущения!$B$22 -> 59399.9 | P5: =MAX(0,D5*Допущения!$B$23+E5*Допущения!$B$24+F5*Допущения!$B$25-G5*Допущения!$B$27)+Допущения!$B$26 -> 32.6 | Q5: =P5/4.33 -> 7.5288684 | R5: 0
A6: 5 | B6: =INT((A6-1)/12)+1 -> 1 | C6: =IF(A6<=3,1,IF(A6<=6,2,IF(A6<=12,3,IF(A6<=24,4,5)))) -> 2 | D6: =INDEX(Объёмы!$B$3:$F$3,C6) -> 0.67 | E6: =INDEX(Объёмы!$B$4:$F$4,C6) -> 0.33 | F6: =INDEX(Объёмы!$B$5:$F$5,C6) -> 0 | G6: =INDEX(Объёмы!$B$6:$F$6,C6) -> 0 | H6: =(D6*Допущения!$B$2+E6*Допущения!$B$3+F6*Допущения!$B$4)*IF(B6=1,1,IF(B6=2,Допущения!$B$8,Допущения!$B$9)) -> 198900 | I6: =(D6*Допущения!$B$2*Допущения!$B$5+E6*Допущения!$B$3*Допущения!$B$6+F6*Допущения!$B$4*Допущения!$B$7)*IF(B6=1,1,IF(B6=2,Допущения!$B$8,Допущения!$B$9)) -> 60570 | J6: =H6-I6 -> 138330 | K6: =INDEX(Допущения!$B$10:$B$14, C6)+G6*Допущения!$B$15 -> 35000 | L6: =IF(R6>Допущения!$B$20,H6*Допущения!$B$21,0) -> 0 | M6: =(H6-L6)*Допущения!$B$16+MAX(0,H6-L6-Допущения!$B$18)*Допущения!$B$17+Допущения!$B$19 -> 18473 | N6: =J6-K6-L6-M6 -> 84857 | O6: =MAX(0,N6)*Допущения!$B$22 -> 59399.9 | P6: =MAX(0,D6*Допущения!$B$23+E6*Допущения!$B$24+F6*Допущения!$B$25-G6*Допущения!$B$27)+Допущения!$B$26 -> 32.6 | Q6: =P6/4.33 -> 7.5288684 | R6: 0
A7: 6 | B7: =INT((A7-1)/12)+1 -> 1 | C7: =IF(A7<=3,1,IF(A7<=6,2,IF(A7<=12,3,IF(A7<=24,4,5)))) -> 2 | D7: =INDEX(Объёмы!$B$3:$F$3,C7) -> 0.67 | E7: =INDEX(Объёмы!$B$4:$F$4,C7) -> 0.33 | F7: =INDEX(Объёмы!$B$5:$F$5,C7) -> 0 | G7: =INDEX(Объёмы!$B$6:$F$6,C7) -> 0 | H7: =(D7*Допущения!$B$2+E7*Допущения!$B$3+F7*Допущения!$B$4)*IF(B7=1,1,IF(B7=2,Допущения!$B$8,Допущения!$B$9)) -> 198900 | I7: =(D7*Допущения!$B$2*Допущения!$B$5+E7*Допущения!$B$3*Допущения!$B$6+F7*Допущения!$B$4*Допущения!$B$7)*IF(B7=1,1,IF(B7=2,Допущения!$B$8,Допущения!$B$9)) -> 60570 | J7: =H7-I7 -> 138330 | K7: =INDEX(Допущения!$B$10:$B$14, C7)+G7*Допущения!$B$15 -> 35000 | L7: =IF(R7>Допущения!$B$20,H7*Допущения!$B$21,0) -> 0 | M7: =(H7-L7)*Допущения!$B$16+MAX(0,H7-L7-Допущения!$B$18)*Допущения!$B$17+Допущения!$B$19 -> 18473 | N7: =J7-K7-L7-M7 -> 84857 | O7: =MAX(0,N7)*Допущения!$B$22 -> 59399.9 | P7: =MAX(0,D7*Допущения!$B$23+E7*Допущения!$B$24+F7*Допущения!$B$25-G7*Допущения!$B$27)+Допущения!$B$26 -> 32.6 | Q7: =P7/4.33 -> 7.5288684 | R7: 0
A8: 7 | B8: =INT((A8-1)/12)+1 -> 1 | C8: =IF(A8<=3,1,IF(A8<=6,2,IF(A8<=12,3,IF(A8<=24,4,5)))) -> 3 | D8: =INDEX(Объёмы!$B$3:$F$3,C8) -> 1 | E8: =INDEX(Объёмы!$B$4:$F$4,C8) -> 0.33 | F8: =INDEX(Объёмы!$B$5:$F$5,C8) -> 1 | G8: =INDEX(Объёмы!$B$6:$F$6,C8) -> 0 | H8: =(D8*Допущения!$B$2+E8*Допущения!$B$3+F8*Допущения!$B$4)*IF(B8=1,1,IF(B8=2,Допущения!$B$8,Допущения!$B$9)) -> 368600 | I8: =(D8*Допущения!$B$2*Допущения!$B$5+E8*Допущения!$B$3*Допущения!$B$6+F8*Допущения!$B$4*Допущения!$B$7)*IF(B8=1,1,IF(B8=2,Допущения!$B$8,Допущения!$B$9)) -> 122510 | J8: =H8-I8 -> 246090 | K8: =INDEX(Допущения!$B$10:$B$14, C8)+G8*Допущения!$B$15 -> 45000 | L8: =IF(R8>Допущения!$B$20,H8*Допущения!$B$21,0) -> 0 | M8: =(H8-L8)*Допущения!$B$16+MAX(0,H8-L8-Допущения!$B$18)*Допущения!$B$17+Допущения!$B$19 -> 30352 | N8: =J8-K8-L8-M8 -> 170738 | O8: =MAX(0,N8)*Допущения!$B$22 -> 119516.6 | P8: =MAX(0,D8*Допущения!$B$23+E8*Допущения!$B$24+F8*Допущения!$B$25-G8*Допущения!$B$27)+Допущения!$B$26 -> 43.9 | Q8: =P8/4.33 -> 10.138568 | R8: 0
A9: 8 | B9: =INT((A9-1)/12)+1 -> 1 | C9: =IF(A9<=3,1,IF(A9<=6,2,IF(A9<=12,3,IF(A9<=24,4,5)))) -> 3 | D9: =INDEX(Объёмы!$B$3:$F$3,C9) -> 1 | E9: =INDEX(Объёмы!$B$4:$F$4,C9) -> 0.33 | F9: =INDEX(Объёмы!$B$5:$F$5,C9) -> 1 | G9: =INDEX(Объёмы!$B$6:$F$6,C9) -> 0 | H9: =(D9*Допущения!$B$2+E9*Допущения!$B$3+F9*Допущения!$B$4)*IF(B9=1,1,IF(B9=2,Допущения!$B$8,Допущения!$B$9)) -> 368600 | I9: =(D9*Допущения!$B$2*Допущения!$B$5+E9*Допущения!$B$3*Допущения!$B$6+F9*Допущения!$B$4*Допущения!$B$7)*IF(B9=1,1,IF(B9=2,Допущения!$B$8,Допущения!$B$9)) -> 122510 | J9: =H9-I9 -> 246090 | K9: =INDEX(Допущения!$B$10:$B$14, C9)+G9*Допущения!$B$15 -> 45000 | L9: =IF(R9>Допущения!$B$20,H9*Допущения!$B$21,0) -> 0 | M9: =(H9-L9)*Допущения!$B$16+MAX(0,H9-L9-Допущения!$B$18)*Допущения!$B$17+Допущения!$B$19 -> 30352 | N9: =J9-K9-L9-M9 -> 170738 | O9: =MAX(0,N9)*Допущения!$B$22 -> 119516.6 | P9: =MAX(0,D9*Допущения!$B$23+E9*Допущения!$B$24+F9*Допущения!$B$25-G9*Допущения!$B$27)+Допущения!$B$26 -> 43.9 | Q9: =P9/4.33 -> 10.138568 | R9: 0
A10: 9 | B10: =INT((A10-1)/12)+1 -> 1 | C10: =IF(A10<=3,1,IF(A10<=6,2,IF(A10<=12,3,IF(A10<=24,4,5)))) -> 3 | D10: =INDEX(Объёмы!$B$3:$F$3,C10) -> 1 | E10: =INDEX(Объёмы!$B$4:$F$4,C10) -> 0.33 | F10: =INDEX(Объёмы!$B$5:$F$5,C10) -> 1 | G10: =INDEX(Объёмы!$B$6:$F$6,C10) -> 0 | H10: =(D10*Допущения!$B$2+E10*Допущения!$B$3+F10*Допущения!$B$4)*IF(B10=1,1,IF(B10=2,Допущения!$B$8,Допущения!$B$9)) -> 368600 | I10: =(D10*Допущения!$B$2*Допущения!$B$5+E10*Допущения!$B$3*Допущения!$B$6+F10*Допущения!$B$4*Допущения!$B$7)*IF(B10=1,1,IF(B10=2,Допущения!$B$8,Допущения!$B$9)) -> 122510 | J10: =H10-I10 -> 246090 | K10: =INDEX(Допущения!$B$10:$B$14, C10)+G10*Допущения!$B$15 -> 45000 | L10: =IF(R10>Допущения!$B$20,H10*Допущения!$B$21,0) -> 0 | M10: =(H10-L10)*Допущения!$B$16+MAX(0,H10-L10-Допущения!$B$18)*Допущения!$B$17+Допущения!$B$19 -> 30352 | N10: =J10-K10-L10-M10 -> 170738 | O10: =MAX(0,N10)*Допущения!$B$22 -> 119516.6 | P10: =MAX(0,D10*Допущения!$B$23+E10*Допущения!$B$24+F10*Допущения!$B$25-G10*Допущения!$B$27)+Допущения!$B$26 -> 43.9 | Q10: =P10/4.33 -> 10.138568 | R10: 0
A11: 10 | B11: =INT((A11-1)/12)+1 -> 1 | C11: =IF(A11<=3,1,IF(A11<=6,2,IF(A11<=12,3,IF(A11<=24,4,5)))) -> 3 | D11: =INDEX(Объёмы!$B$3:$F$3,C11) -> 1 | E11: =INDEX(Объёмы!$B$4:$F$4,C11) -> 0.33 | F11: =INDEX(Объёмы!$B$5:$F$5,C11) -> 1 | G11: =INDEX(Объёмы!$B$6:$F$6,C11) -> 0 | H11: =(D11*Допущения!$B$2+E11*Допущения!$B$3+F11*Допущения!$B$4)*IF(B11=1,1,IF(B11=2,Допущения!$B$8,Допущения!$B$9)) -> 368600 | I11: =(D11*Допущения!$B$2*Допущения!$B$5+E11*Допущения!$B$3*Допущения!$B$6+F11*Допущения!$B$4*Допущения!$B$7)*IF(B11=1,1,IF(B11=2,Допущения!$B$8,Допущения!$B$9)) -> 122510 | J11: =H11-I11 -> 246090 | K11: =INDEX(Допущения!$B$10:$B$14, C11)+G11*Допущения!$B$15 -> 45000 | L11: =IF(R11>Допущения!$B$20,H11*Допущения!$B$21,0) -> 0 | M11: =(H11-L11)*Допущения!$B$16+MAX(0,H11-L11-Допущения!$B$18)*Допущения!$B$17+Допущения!$B$19 -> 30352 | N11: =J11-K11-L11-M11 -> 170738 | O11: =MAX(0,N11)*Допущения!$B$22 -> 119516.6 | P11: =MAX(0,D11*Допущения!$B$23+E11*Допущения!$B$24+F11*Допущения!$B$25-G11*Допущения!$B$27)+Допущения!$B$26 -> 43.9 | Q11: =P11/4.33 -> 10.138568 | R11: 0
A12: 11 | B12: =INT((A12-1)/12)+1 -> 1 | C12: =IF(A12<=3,1,IF(A12<=6,2,IF(A12<=12,3,IF(A12<=24,4,5)))) -> 3 | D12: =INDEX(Объёмы!$B$3:$F$3,C12) -> 1 | E12: =INDEX(Объёмы!$B$4:$F$4,C12) -> 0.33 | F12: =INDEX(Объёмы!$B$5:$F$5,C12) -> 1 | G12: =INDEX(Объёмы!$B$6:$F$6,C12) -> 0 | H12: =(D12*Допущения!$B$2+E12*Допущения!$B$3+F12*Допущения!$B$4)*IF(B12=1,1,IF(B12=2,Допущения!$B$8,Допущения!$B$9)) -> 368600 | I12: =(D12*Допущения!$B$2*Допущения!$B$5+E12*Допущения!$B$3*Допущения!$B$6+F12*Допущения!$B$4*Допущения!$B$7)*IF(B12=1,1,IF(B12=2,Допущения!$B$8,Допущения!$B$9)) -> 122510 | J12: =H12-I12 -> 246090 | K12: =INDEX(Допущения!$B$10:$B$14, C12)+G12*Допущения!$B$15 -> 45000 | L12: =IF(R12>Допущения!$B$20,H12*Допущения!$B$21,0) -> 0 | M12: =(H12-L12)*Допущения!$B$16+MAX(0,H12-L12-Допущения!$B$18)*Допущения!$B$17+Допущения!$B$19 -> 30352 | N12: =J12-K12-L12-M12 -> 170738 | O12: =MAX(0,N12)*Допущения!$B$22 -> 119516.6 | P12: =MAX(0,D12*Допущения!$B$23+E12*Допущения!$B$24+F12*Допущения!$B$25-G12*Допущения!$B$27)+Допущения!$B$26 -> 43.9 | Q12: =P12/4.33 -> 10.138568 | R12: 0
A13: 12 | B13: =INT((A13-1)/12)+1 -> 1 | C13: =IF(A13<=3,1,IF(A13<=6,2,IF(A13<=12,3,IF(A13<=24,4,5)))) -> 3 | D13: =INDEX(Объёмы!$B$3:$F$3,C13) -> 1 | E13: =INDEX(Объёмы!$B$4:$F$4,C13) -> 0.33 | F13: =INDEX(Объёмы!$B$5:$F$5,C13) -> 1 | G13: =INDEX(Объёмы!$B$6:$F$6,C13) -> 0 | H13: =(D13*Допущения!$B$2+E13*Допущения!$B$3+F13*Допущения!$B$4)*IF(B13=1,1,IF(B13=2,Допущения!$B$8,Допущения!$B$9)) -> 368600 | I13: =(D13*Допущения!$B$2*Допущения!$B$5+E13*Допущения!$B$3*Допущения!$B$6+F13*Допущения!$B$4*Допущения!$B$7)*IF(B13=1,1,IF(B13=2,Допущения!$B$8,Допущения!$B$9)) -> 122510 | J13: =H13-I13 -> 246090 | K13: =INDEX(Допущения!$B$10:$B$14, C13)+G13*Допущения!$B$15 -> 45000 | L13: =IF(R13>Допущения!$B$20,H13*Допущения!$B$21,0) -> 0 | M13: =(H13-L13)*Допущения!$B$16+MAX(0,H13-L13-Допущения!$B$18)*Допущения!$B$17+Допущения!$B$19 -> 30352 | N13: =J13-K13-L13-M13 -> 170738 | O13: =MAX(0,N13)*Допущения!$B$22 -> 119516.6 | P13: =MAX(0,D13*Допущения!$B$23+E13*Допущения!$B$24+F13*Допущения!$B$25-G13*Допущения!$B$27)+Допущения!$B$26 -> 43.9 | Q13: =P13/4.33 -> 10.138568 | R13: 0
A14: 13 | B14: =INT((A14-1)/12)+1 -> 2 | C14: =IF(A14<=3,1,IF(A14<=6,2,IF(A14<=12,3,IF(A14<=24,4,5)))) -> 4 | D14: =INDEX(Объёмы!$B$3:$F$3,C14) -> 1.5 | E14: =INDEX(Объёмы!$B$4:$F$4,C14) -> 0.5 | F14: =INDEX(Объёмы!$B$5:$F$5,C14) -> 2 | G14: =INDEX(Объёмы!$B$6:$F$6,C14) -> 0 | H14: =(D14*Допущения!$B$2+E14*Допущения!$B$3+F14*Допущения!$B$4)*IF(B14=1,1,IF(B14=2,Допущения!$B$8,Допущения!$B$9)) -> 687500 | I14: =(D14*Допущения!$B$2*Допущения!$B$5+E14*Допущения!$B$3*Допущения!$B$6+F14*Допущения!$B$4*Допущения!$B$7)*IF(B14=1,1,IF(B14=2,Допущения!$B$8,Допущения!$B$9)) -> 233750 | J14: =H14-I14 -> 453750 | K14: =INDEX(Допущения!$B$10:$B$14, C14)+G14*Допущения!$B$15 -> 70000 | L14: =IF(R14>Допущения!$B$20,H14*Допущения!$B$21,0) -> 0 | M14: =(H14-L14)*Допущения!$B$16+MAX(0,H14-L14-Допущения!$B$18)*Допущения!$B$17+Допущения!$B$19 -> 52675 | N14: =J14-K14-L14-M14 -> 331075 | O14: =MAX(0,N14)*Допущения!$B$22 -> 231752.5 | P14: =MAX(0,D14*Допущения!$B$23+E14*Допущения!$B$24+F14*Допущения!$B$25-G14*Допущения!$B$27)+Допущения!$B$26 -> 62 | Q14: =P14/4.33 -> 14.318707 | R14: =SUM(H2:H13) -> 2897400
A15: 14 | B15: =INT((A15-1)/12)+1 -> 2 | C15: =IF(A15<=3,1,IF(A15<=6,2,IF(A15<=12,3,IF(A15<=24,4,5)))) -> 4 | D15: =INDEX(Объёмы!$B$3:$F$3,C15) -> 1.5 | E15: =INDEX(Объёмы!$B$4:$F$4,C15) -> 0.5 | F15: =INDEX(Объёмы!$B$5:$F$5,C15) -> 2 | G15: =INDEX(Объёмы!$B$6:$F$6,C15) -> 0 | H15: =(D15*Допущения!$B$2+E15*Допущения!$B$3+F15*Допущения!$B$4)*IF(B15=1,1,IF(B15=2,Допущения!$B$8,Допущения!$B$9)) -> 687500 | I15: =(D15*Допущения!$B$2*Допущения!$B$5+E15*Допущения!$B$3*Допущения!$B$6+F15*Допущения!$B$4*Допущения!$B$7)*IF(B15=1,1,IF(B15=2,Допущения!$B$8,Допущения!$B$9)) -> 233750 | J15: =H15-I15 -> 453750 | K15: =INDEX(Допущения!$B$10:$B$14, C15)+G15*Допущения!$B$15 -> 70000 | L15: =IF(R15>Допущения!$B$20,H15*Допущения!$B$21,0) -> 0 | M15: =(H15-L15)*Допущения!$B$16+MAX(0,H15-L15-Допущения!$B$18)*Допущения!$B$17+Допущения!$B$19 -> 52675 | N15: =J15-K15-L15-M15 -> 331075 | O15: =MAX(0,N15)*Допущения!$B$22 -> 231752.5 | P15: =MAX(0,D15*Допущения!$B$23+E15*Допущения!$B$24+F15*Допущения!$B$25-G15*Допущения!$B$27)+Допущения!$B$26 -> 62 | Q15: =P15/4.33 -> 14.318707 | R15: =SUM(H2:H13) -> 2897400
A16: 15 | B16: =INT((A16-1)/12)+1 -> 2 | C16: =IF(A16<=3,1,IF(A16<=6,2,IF(A16<=12,3,IF(A16<=24,4,5)))) -> 4 | D16: =INDEX(Объёмы!$B$3:$F$3,C16) -> 1.5 | E16: =INDEX(Объёмы!$B$4:$F$4,C16) -> 0.5 | F16: =INDEX(Объёмы!$B$5:$F$5,C16) -> 2 | G16: =INDEX(Объёмы!$B$6:$F$6,C16) -> 0 | H16: =(D16*Допущения!$B$2+E16*Допущения!$B$3+F16*Допущения!$B$4)*IF(B16=1,1,IF(B16=2,Допущения!$B$8,Допущения!$B$9)) -> 687500 | I16: =(D16*Допущения!$B$2*Допущения!$B$5+E16*Допущения!$B$3*Допущения!$B$6+F16*Допущения!$B$4*Допущения!$B$7)*IF(B16=1,1,IF(B16=2,Допущения!$B$8,Допущения!$B$9)) -> 233750 | J16: =H16-I16 -> 453750 | K16: =INDEX(Допущения!$B$10:$B$14, C16)+G16*Допущения!$B$15 -> 70000 | L16: =IF(R16>Допущения!$B$20,H16*Допущения!$B$21,0) -> 0 | M16: =(H16-L16)*Допущения!$B$16+MAX(0,H16-L16-Допущения!$B$18)*Допущения!$B$17+Допущения!$B$19 -> 52675 | N16: =J16-K16-L16-M16 -> 331075 | O16: =MAX(0,N16)*Допущения!$B$22 -> 231752.5 | P16: =MAX(0,D16*Допущения!$B$23+E16*Допущения!$B$24+F16*Допущения!$B$25-G16*Допущения!$B$27)+Допущения!$B$26 -> 62 | Q16: =P16/4.33 -> 14.318707 | R16: =SUM(H2:H13) -> 2897400
A17: 16 | B17: =INT((A17-1)/12)+1 -> 2 | C17: =IF(A17<=3,1,IF(A17<=6,2,IF(A17<=12,3,IF(A17<=24,4,5)))) -> 4 | D17: =INDEX(Объёмы!$B$3:$F$3,C17) -> 1.5 | E17: =INDEX(Объёмы!$B$4:$F$4,C17) -> 0.5 | F17: =INDEX(Объёмы!$B$5:$F$5,C17) -> 2 | G17: =INDEX(Объёмы!$B$6:$F$6,C17) -> 0 | H17: =(D17*Допущения!$B$2+E17*Допущения!$B$3+F17*Допущения!$B$4)*IF(B17=1,1,IF(B17=2,Допущения!$B$8,Допущения!$B$9)) -> 687500 | I17: =(D17*Допущения!$B$2*Допущения!$B$5+E17*Допущения!$B$3*Допущения!$B$6+F17*Допущения!$B$4*Допущения!$B$7)*IF(B17=1,1,IF(B17=2,Допущения!$B$8,Допущения!$B$9)) -> 233750 | J17: =H17-I17 -> 453750 | K17: =INDEX(Допущения!$B$10:$B$14, C17)+G17*Допущения!$B$15 -> 70000 | L17: =IF(R17>Допущения!$B$20,H17*Допущения!$B$21,0) -> 0 | M17: =(H17-L17)*Допущения!$B$16+MAX(0,H17-L17-Допущения!$B$18)*Допущения!$B$17+Допущения!$B$19 -> 52675 | N17: =J17-K17-L17-M17 -> 331075 | O17: =MAX(0,N17)*Допущения!$B$22 -> 231752.5 | P17: =MAX(0,D17*Допущения!$B$23+E17*Допущения!$B$24+F17*Допущения!$B$25-G17*Допущения!$B$27)+Допущения!$B$26 -> 62 | Q17: =P17/4.33 -> 14.318707 | R17: =SUM(H2:H13) -> 2897400
A18: 17 | B18: =INT((A18-1)/12)+1 -> 2 | C18: =IF(A18<=3,1,IF(A18<=6,2,IF(A18<=12,3,IF(A18<=24,4,5)))) -> 4 | D18: =INDEX(Объёмы!$B$3:$F$3,C18) -> 1.5 | E18: =INDEX(Объёмы!$B$4:$F$4,C18) -> 0.5 | F18: =INDEX(Объёмы!$B$5:$F$5,C18) -> 2 | G18: =INDEX(Объёмы!$B$6:$F$6,C18) -> 0 | H18: =(D18*Допущения!$B$2+E18*Допущения!$B$3+F18*Допущения!$B$4)*IF(B18=1,1,IF(B18=2,Допущения!$B$8,Допущения!$B$9)) -> 687500 | I18: =(D18*Допущения!$B$2*Допущения!$B$5+E18*Допущения!$B$3*Допущения!$B$6+F18*Допущения!$B$4*Допущения!$B$7)*IF(B18=1,1,IF(B18=2,Допущения!$B$8,Допущения!$B$9)) -> 233750 | J18: =H18-I18 -> 453750 | K18: =INDEX(Допущения!$B$10:$B$14, C18)+G18*Допущения!$B$15 -> 70000 | L18: =IF(R18>Допущения!$B$20,H18*Допущения!$B$21,0) -> 0 | M18: =(H18-L18)*Допущения!$B$16+MAX(0,H18-L18-Допущения!$B$18)*Допущения!$B$17+Допущения!$B$19 -> 52675 | N18: =J18-K18-L18-M18 -> 331075 | O18: =MAX(0,N18)*Допущения!$B$22 -> 231752.5 | P18: =MAX(0,D18*Допущения!$B$23+E18*Допущения!$B$24+F18*Допущения!$B$25-G18*Допущения!$B$27)+Допущения!$B$26 -> 62 | Q18: =P18/4.33 -> 14.318707 | R18: =SUM(H2:H13) -> 2897400
A19: 18 | B19: =INT((A19-1)/12)+1 -> 2 | C19: =IF(A19<=3,1,IF(A19<=6,2,IF(A19<=12,3,IF(A19<=24,4,5)))) -> 4 | D19: =INDEX(Объёмы!$B$3:$F$3,C19) -> 1.5 | E19: =INDEX(Объёмы!$B$4:$F$4,C19) -> 0.5 | F19: =INDEX(Объёмы!$B$5:$F$5,C19) -> 2 | G19: =INDEX(Объёмы!$B$6:$F$6,C19) -> 0 | H19: =(D19*Допущения!$B$2+E19*Допущения!$B$3+F19*Допущения!$B$4)*IF(B19=1,1,IF(B19=2,Допущения!$B$8,Допущения!$B$9)) -> 687500 | I19: =(D19*Допущения!$B$2*Допущения!$B$5+E19*Допущения!$B$3*Допущения!$B$6+F19*Допущения!$B$4*Допущения!$B$7)*IF(B19=1,1,IF(B19=2,Допущения!$B$8,Допущения!$B$9)) -> 233750 | J19: =H19-I19 -> 453750 | K19: =INDEX(Допущения!$B$10:$B$14, C19)+G19*Допущения!$B$15 -> 70000 | L19: =IF(R19>Допущения!$B$20,H19*Допущения!$B$21,0) -> 0 | M19: =(H19-L19)*Допущения!$B$16+MAX(0,H19-L19-Допущения!$B$18)*Допущения!$B$17+Допущения!$B$19 -> 52675 | N19: =J19-K19-L19-M19 -> 331075 | O19: =MAX(0,N19)*Допущения!$B$22 -> 231752.5 | P19: =MAX(0,D19*Допущения!$B$23+E19*Допущения!$B$24+F19*Допущения!$B$25-G19*Допущения!$B$27)+Допущения!$B$26 -> 62 | Q19: =P19/4.33 -> 14.318707 | R19: =SUM(H2:H13) -> 2897400
A20: 19 | B20: =INT((A20-1)/12)+1 -> 2 | C20: =IF(A20<=3,1,IF(A20<=6,2,IF(A20<=12,3,IF(A20<=24,4,5)))) -> 4 | D20: =INDEX(Объёмы!$B$3:$F$3,C20) -> 1.5 | E20: =INDEX(Объёмы!$B$4:$F$4,C20) -> 0.5 | F20: =INDEX(Объёмы!$B$5:$F$5,C20) -> 2 | G20: =INDEX(Объёмы!$B$6:$F$6,C20) -> 0 | H20: =(D20*Допущения!$B$2+E20*Допущения!$B$3+F20*Допущения!$B$4)*IF(B20=1,1,IF(B20=2,Допущения!$B$8,Допущения!$B$9)) -> 687500 | I20: =(D20*Допущения!$B$2*Допущения!$B$5+E20*Допущения!$B$3*Допущения!$B$6+F20*Допущения!$B$4*Допущения!$B$7)*IF(B20=1,1,IF(B20=2,Допущения!$B$8,Допущения!$B$9)) -> 233750 | J20: =H20-I20 -> 453750 | K20: =INDEX(Допущения!$B$10:$B$14, C20)+G20*Допущения!$B$15 -> 70000 | L20: =IF(R20>Допущения!$B$20,H20*Допущения!$B$21,0) -> 0 | M20: =(H20-L20)*Допущения!$B$16+MAX(0,H20-L20-Допущения!$B$18)*Допущения!$B$17+Допущения!$B$19 -> 52675 | N20: =J20-K20-L20-M20 -> 331075 | O20: =MAX(0,N20)*Допущения!$B$22 -> 231752.5 | P20: =MAX(0,D20*Допущения!$B$23+E20*Допущения!$B$24+F20*Допущения!$B$25-G20*Допущения!$B$27)+Допущения!$B$26 -> 62 | Q20: =P20/4.33 -> 14.318707 | R20: =SUM(H2:H13) -> 2897400
A21: 20 | B21: =INT((A21-1)/12)+1 -> 2 | C21: =IF(A21<=3,1,IF(A21<=6,2,IF(A21<=12,3,IF(A21<=24,4,5)))) -> 4 | D21: =INDEX(Объёмы!$B$3:$F$3,C21) -> 1.5 | E21: =INDEX(Объёмы!$B$4:$F$4,C21) -> 0.5 | F21: =INDEX(Объёмы!$B$5:$F$5,C21) -> 2 | G21: =INDEX(Объёмы!$B$6:$F$6,C21) -> 0 | H21: =(D21*Допущения!$B$2+E21*Допущения!$B$3+F21*Допущения!$B$4)*IF(B21=1,1,IF(B21=2,Допущения!$B$8,Допущения!$B$9)) -> 687500 | I21: =(D21*Допущения!$B$2*Допущения!$B$5+E21*Допущения!$B$3*Допущения!$B$6+F21*Допущения!$B$4*Допущения!$B$7)*IF(B21=1,1,IF(B21=2,Допущения!$B$8,Допущения!$B$9)) -> 233750 | J21: =H21-I21 -> 453750 | K21: =INDEX(Допущения!$B$10:$B$14, C21)+G21*Допущения!$B$15 -> 70000 | L21: =IF(R21>Допущения!$B$20,H21*Допущения!$B$21,0) -> 0 | M21: =(H21-L21)*Допущения!$B$16+MAX(0,H21-L21-Допущения!$B$18)*Допущения!$B$17+Допущения!$B$19 -> 52675 | N21: =J21-K21-L21-M21 -> 331075 | O21: =MAX(0,N21)*Допущения!$B$22 -> 231752.5 | P21: =MAX(0,D21*Допущения!$B$23+E21*Допущения!$B$24+F21*Допущения!$B$25-G21*Допущения!$B$27)+Допущения!$B$26 -> 62 | Q21: =P21/4.33 -> 14.318707 | R21: =SUM(H2:H13) -> 2897400
A22: 21 | B22: =INT((A22-1)/12)+1 -> 2 | C22: =IF(A22<=3,1,IF(A22<=6,2,IF(A22<=12,3,IF(A22<=24,4,5)))) -> 4 | D22: =INDEX(Объёмы!$B$3:$F$3,C22) -> 1.5 | E22: =INDEX(Объёмы!$B$4:$F$4,C22) -> 0.5 | F22: =INDEX(Объёмы!$B$5:$F$5,C22) -> 2 | G22: =INDEX(Объёмы!$B$6:$F$6,C22) -> 0 | H22: =(D22*Допущения!$B$2+E22*Допущения!$B$3+F22*Допущения!$B$4)*IF(B22=1,1,IF(B22=2,Допущения!$B$8,Допущения!$B$9)) -> 687500 | I22: =(D22*Допущения!$B$2*Допущения!$B$5+E22*Допущения!$B$3*Допущения!$B$6+F22*Допущения!$B$4*Допущения!$B$7)*IF(B22=1,1,IF(B22=2,Допущения!$B$8,Допущения!$B$9)) -> 233750 | J22: =H22-I22 -> 453750 | K22: =INDEX(Допущения!$B$10:$B$14, C22)+G22*Допущения!$B$15 -> 70000 | L22: =IF(R22>Допущения!$B$20,H22*Допущения!$B$21,0) -> 0 | M22: =(H22-L22)*Допущения!$B$16+MAX(0,H22-L22-Допущения!$B$18)*Допущения!$B$17+Допущения!$B$19 -> 52675 | N22: =J22-K22-L22-M22 -> 331075 | O22: =MAX(0,N22)*Допущения!$B$22 -> 231752.5 | P22: =MAX(0,D22*Допущения!$B$23+E22*Допущения!$B$24+F22*Допущения!$B$25-G22*Допущения!$B$27)+Допущения!$B$26 -> 62 | Q22: =P22/4.33 -> 14.318707 | R22: =SUM(H2:H13) -> 2897400
A23: 22 | B23: =INT((A23-1)/12)+1 -> 2 | C23: =IF(A23<=3,1,IF(A23<=6,2,IF(A23<=12,3,IF(A23<=24,4,5)))) -> 4 | D23: =INDEX(Объёмы!$B$3:$F$3,C23) -> 1.5 | E23: =INDEX(Объёмы!$B$4:$F$4,C23) -> 0.5 | F23: =INDEX(Объёмы!$B$5:$F$5,C23) -> 2 | G23: =INDEX(Объёмы!$B$6:$F$6,C23) -> 0 | H23: =(D23*Допущения!$B$2+E23*Допущения!$B$3+F23*Допущения!$B$4)*IF(B23=1,1,IF(B23=2,Допущения!$B$8,Допущения!$B$9)) -> 687500 | I23: =(D23*Допущения!$B$2*Допущения!$B$5+E23*Допущения!$B$3*Допущения!$B$6+F23*Допущения!$B$4*Допущения!$B$7)*IF(B23=1,1,IF(B23=2,Допущения!$B$8,Допущения!$B$9)) -> 233750 | J23: =H23-I23 -> 453750 | K23: =INDEX(Допущения!$B$10:$B$14, C23)+G23*Допущения!$B$15 -> 70000 | L23: =IF(R23>Допущения!$B$20,H23*Допущения!$B$21,0) -> 0 | M23: =(H23-L23)*Допущения!$B$16+MAX(0,H23-L23-Допущения!$B$18)*Допущения!$B$17+Допущения!$B$19 -> 52675 | N23: =J23-K23-L23-M23 -> 331075 | O23: =MAX(0,N23)*Допущения!$B$22 -> 231752.5 | P23: =MAX(0,D23*Допущения!$B$23+E23*Допущения!$B$24+F23*Допущения!$B$25-G23*Допущения!$B$27)+Допущения!$B$26 -> 62 | Q23: =P23/4.33 -> 14.318707 | R23: =SUM(H2:H13) -> 2897400
A24: 23 | B24: =INT((A24-1)/12)+1 -> 2 | C24: =IF(A24<=3,1,IF(A24<=6,2,IF(A24<=12,3,IF(A24<=24,4,5)))) -> 4 | D24: =INDEX(Объёмы!$B$3:$F$3,C24) -> 1.5 | E24: =INDEX(Объёмы!$B$4:$F$4,C24) -> 0.5 | F24: =INDEX(Объёмы!$B$5:$F$5,C24) -> 2 | G24: =INDEX(Объёмы!$B$6:$F$6,C24) -> 0 | H24: =(D24*Допущения!$B$2+E24*Допущения!$B$3+F24*Допущения!$B$4)*IF(B24=1,1,IF(B24=2,Допущения!$B$8,Допущения!$B$9)) -> 687500 | I24: =(D24*Допущения!$B$2*Допущения!$B$5+E24*Допущения!$B$3*Допущения!$B$6+F24*Допущения!$B$4*Допущения!$B$7)*IF(B24=1,1,IF(B24=2,Допущения!$B$8,Допущения!$B$9)) -> 233750 | J24: =H24-I24 -> 453750 | K24: =INDEX(Допущения!$B$10:$B$14, C24)+G24*Допущения!$B$15 -> 70000 | L24: =IF(R24>Допущения!$B$20,H24*Допущения!$B$21,0) -> 0 | M24: =(H24-L24)*Допущения!$B$16+MAX(0,H24-L24-Допущения!$B$18)*Допущения!$B$17+Допущения!$B$19 -> 52675 | N24: =J24-K24-L24-M24 -> 331075 | O24: =MAX(0,N24)*Допущения!$B$22 -> 231752.5 | P24: =MAX(0,D24*Допущения!$B$23+E24*Допущения!$B$24+F24*Допущения!$B$25-G24*Допущения!$B$27)+Допущения!$B$26 -> 62 | Q24: =P24/4.33 -> 14.318707 | R24: =SUM(H2:H13) -> 2897400
A25: 24 | B25: =INT((A25-1)/12)+1 -> 2 | C25: =IF(A25<=3,1,IF(A25<=6,2,IF(A25<=12,3,IF(A25<=24,4,5)))) -> 4 | D25: =INDEX(Объёмы!$B$3:$F$3,C25) -> 1.5 | E25: =INDEX(Объёмы!$B$4:$F$4,C25) -> 0.5 | F25: =INDEX(Объёмы!$B$5:$F$5,C25) -> 2 | G25: =INDEX(Объёмы!$B$6:$F$6,C25) -> 0 | H25: =(D25*Допущения!$B$2+E25*Допущения!$B$3+F25*Допущения!$B$4)*IF(B25=1,1,IF(B25=2,Допущения!$B$8,Допущения!$B$9)) -> 687500 | I25: =(D25*Допущения!$B$2*Допущения!$B$5+E25*Допущения!$B$3*Допущения!$B$6+F25*Допущения!$B$4*Допущения!$B$7)*IF(B25=1,1,IF(B25=2,Допущения!$B$8,Допущения!$B$9)) -> 233750 | J25: =H25-I25 -> 453750 | K25: =INDEX(Допущения!$B$10:$B$14, C25)+G25*Допущения!$B$15 -> 70000 | L25: =IF(R25>Допущения!$B$20,H25*Допущения!$B$21,0) -> 0 | M25: =(H25-L25)*Допущения!$B$16+MAX(0,H25-L25-Допущения!$B$18)*Допущения!$B$17+Допущения!$B$19 -> 52675 | N25: =J25-K25-L25-M25 -> 331075 | O25: =MAX(0,N25)*Допущения!$B$22 -> 231752.5 | P25: =MAX(0,D25*Допущения!$B$23+E25*Допущения!$B$24+F25*Допущения!$B$25-G25*Допущения!$B$27)+Допущения!$B$26 -> 62 | Q25: =P25/4.33 -> 14.318707 | R25: =SUM(H2:H13) -> 2897400
A26: 25 | B26: =INT((A26-1)/12)+1 -> 3 | C26: =IF(A26<=3,1,IF(A26<=6,2,IF(A26<=12,3,IF(A26<=24,4,5)))) -> 5 | D26: =INDEX(Объёмы!$B$3:$F$3,C26) -> 2 | E26: =INDEX(Объёмы!$B$4:$F$4,C26) -> 0.75 | F26: =INDEX(Объёмы!$B$5:$F$5,C26) -> 3 | G26: =INDEX(Объёмы!$B$6:$F$6,C26) -> 1 | H26: =(D26*Допущения!$B$2+E26*Допущения!$B$3+F26*Допущения!$B$4)*IF(B26=1,1,IF(B26=2,Допущения!$B$8,Допущения!$B$9)) -> 1098000 | I26: =(D26*Допущения!$B$2*Допущения!$B$5+E26*Допущения!$B$3*Допущения!$B$6+F26*Допущения!$B$4*Допущения!$B$7)*IF(B26=1,1,IF(B26=2,Допущения!$B$8,Допущения!$B$9)) -> 377100 | J26: =H26-I26 -> 720900 | K26: =INDEX(Допущения!$B$10:$B$14, C26)+G26*Допущения!$B$15 -> 260000 | L26: =IF(R26>Допущения!$B$20,H26*Допущения!$B$21,0) -> 0 | M26: =(H26-L26)*Допущения!$B$16+MAX(0,H26-L26-Допущения!$B$18)*Допущения!$B$17+Допущения!$B$19 -> 81410 | N26: =J26-K26-L26-M26 -> 379490 | O26: =MAX(0,N26)*Допущения!$B$22 -> 265643 | P26: =MAX(0,D26*Допущения!$B$23+E26*Допущения!$B$24+F26*Допущения!$B$25-G26*Допущения!$B$27)+Допущения!$B$26 -> 42.5 | Q26: =P26/4.33 -> 9.8152425 | R26: =SUM(H14:H25) -> 8250000
A27: 26 | B27: =INT((A27-1)/12)+1 -> 3 | C27: =IF(A27<=3,1,IF(A27<=6,2,IF(A27<=12,3,IF(A27<=24,4,5)))) -> 5 | D27: =INDEX(Объёмы!$B$3:$F$3,C27) -> 2 | E27: =INDEX(Объёмы!$B$4:$F$4,C27) -> 0.75 | F27: =INDEX(Объёмы!$B$5:$F$5,C27) -> 3 | G27: =INDEX(Объёмы!$B$6:$F$6,C27) -> 1 | H27: =(D27*Допущения!$B$2+E27*Допущения!$B$3+F27*Допущения!$B$4)*IF(B27=1,1,IF(B27=2,Допущения!$B$8,Допущения!$B$9)) -> 1098000 | I27: =(D27*Допущения!$B$2*Допущения!$B$5+E27*Допущения!$B$3*Допущения!$B$6+F27*Допущения!$B$4*Допущения!$B$7)*IF(B27=1,1,IF(B27=2,Допущения!$B$8,Допущения!$B$9)) -> 377100 | J27: =H27-I27 -> 720900 | K27: =INDEX(Допущения!$B$10:$B$14, C27)+G27*Допущения!$B$15 -> 260000 | L27: =IF(R27>Допущения!$B$20,H27*Допущения!$B$21,0) -> 0 | M27: =(H27-L27)*Допущения!$B$16+MAX(0,H27-L27-Допущения!$B$18)*Допущения!$B$17+Допущения!$B$19 -> 81410 | N27: =J27-K27-L27-M27 -> 379490 | O27: =MAX(0,N27)*Допущения!$B$22 -> 265643 | P27: =MAX(0,D27*Допущения!$B$23+E27*Допущения!$B$24+F27*Допущения!$B$25-G27*Допущения!$B$27)+Допущения!$B$26 -> 42.5 | Q27: =P27/4.33 -> 9.8152425 | R27: =SUM(H14:H25) -> 8250000
A28: 27 | B28: =INT((A28-1)/12)+1 -> 3 | C28: =IF(A28<=3,1,IF(A28<=6,2,IF(A28<=12,3,IF(A28<=24,4,5)))) -> 5 | D28: =INDEX(Объёмы!$B$3:$F$3,C28) -> 2 | E28: =INDEX(Объёмы!$B$4:$F$4,C28) -> 0.75 | F28: =INDEX(Объёмы!$B$5:$F$5,C28) -> 3 | G28: =INDEX(Объёмы!$B$6:$F$6,C28) -> 1 | H28: =(D28*Допущения!$B$2+E28*Допущения!$B$3+F28*Допущения!$B$4)*IF(B28=1,1,IF(B28=2,Допущения!$B$8,Допущения!$B$9)) -> 1098000 | I28: =(D28*Допущения!$B$2*Допущения!$B$5+E28*Допущения!$B$3*Допущения!$B$6+F28*Допущения!$B$4*Допущения!$B$7)*IF(B28=1,1,IF(B28=2,Допущения!$B$8,Допущения!$B$9)) -> 377100 | J28: =H28-I28 -> 720900 | K28: =INDEX(Допущения!$B$10:$B$14, C28)+G28*Допущения!$B$15 -> 260000 | L28: =IF(R28>Допущения!$B$20,H28*Допущения!$B$21,0) -> 0 | M28: =(H28-L28)*Допущения!$B$16+MAX(0,H28-L28-Допущения!$B$18)*Допущения!$B$17+Допущения!$B$19 -> 81410 | N28: =J28-K28-L28-M28 -> 379490 | O28: =MAX(0,N28)*Допущения!$B$22 -> 265643 | P28: =MAX(0,D28*Допущения!$B$23+E28*Допущения!$B$24+F28*Допущения!$B$25-G28*Допущения!$B$27)+Допущения!$B$26 -> 42.5 | Q28: =P28/4.33 -> 9.8152425 | R28: =SUM(H14:H25) -> 8250000
A29: 28 | B29: =INT((A29-1)/12)+1 -> 3 | C29: =IF(A29<=3,1,IF(A29<=6,2,IF(A29<=12,3,IF(A29<=24,4,5)))) -> 5 | D29: =INDEX(Объёмы!$B$3:$F$3,C29) -> 2 | E29: =INDEX(Объёмы!$B$4:$F$4,C29) -> 0.75 | F29: =INDEX(Объёмы!$B$5:$F$5,C29) -> 3 | G29: =INDEX(Объёмы!$B$6:$F$6,C29) -> 1 | H29: =(D29*Допущения!$B$2+E29*Допущения!$B$3+F29*Допущения!$B$4)*IF(B29=1,1,IF(B29=2,Допущения!$B$8,Допущения!$B$9)) -> 1098000 | I29: =(D29*Допущения!$B$2*Допущения!$B$5+E29*Допущения!$B$3*Допущения!$B$6+F29*Допущения!$B$4*Допущения!$B$7)*IF(B29=1,1,IF(B29=2,Допущения!$B$8,Допущения!$B$9)) -> 377100 | J29: =H29-I29 -> 720900 | K29: =INDEX(Допущения!$B$10:$B$14, C29)+G29*Допущения!$B$15 -> 260000 | L29: =IF(R29>Допущения!$B$20,H29*Допущения!$B$21,0) -> 0 | M29: =(H29-L29)*Допущения!$B$16+MAX(0,H29-L29-Допущения!$B$18)*Допущения!$B$17+Допущения!$B$19 -> 81410 | N29: =J29-K29-L29-M29 -> 379490 | O29: =MAX(0,N29)*Допущения!$B$22 -> 265643 | P29: =MAX(0,D29*Допущения!$B$23+E29*Допущения!$B$24+F29*Допущения!$B$25-G29*Допущения!$B$27)+Допущения!$B$26 -> 42.5 | Q29: =P29/4.33 -> 9.8152425 | R29: =SUM(H14:H25) -> 8250000
A30: 29 | B30: =INT((A30-1)/12)+1 -> 3 | C30: =IF(A30<=3,1,IF(A30<=6,2,IF(A30<=12,3,IF(A30<=24,4,5)))) -> 5 | D30: =INDEX(Объёмы!$B$3:$F$3,C30) -> 2 | E30: =INDEX(Объёмы!$B$4:$F$4,C30) -> 0.75 | F30: =INDEX(Объёмы!$B$5:$F$5,C30) -> 3 | G30: =INDEX(Объёмы!$B$6:$F$6,C30) -> 1 | H30: =(D30*Допущения!$B$2+E30*Допущения!$B$3+F30*Допущения!$B$4)*IF(B30=1,1,IF(B30=2,Допущения!$B$8,Допущения!$B$9)) -> 1098000 | I30: =(D30*Допущения!$B$2*Допущения!$B$5+E30*Допущения!$B$3*Допущения!$B$6+F30*Допущения!$B$4*Допущения!$B$7)*IF(B30=1,1,IF(B30=2,Допущения!$B$8,Допущения!$B$9)) -> 377100 | J30: =H30-I30 -> 720900 | K30: =INDEX(Допущения!$B$10:$B$14, C30)+G30*Допущения!$B$15 -> 260000 | L30: =IF(R30>Допущения!$B$20,H30*Допущения!$B$21,0) -> 0 | M30: =(H30-L30)*Допущения!$B$16+MAX(0,H30-L30-Допущения!$B$18)*Допущения!$B$17+Допущения!$B$19 -> 81410 | N30: =J30-K30-L30-M30 -> 379490 | O30: =MAX(0,N30)*Допущения!$B$22 -> 265643 | P30: =MAX(0,D30*Допущения!$B$23+E30*Допущения!$B$24+F30*Допущения!$B$25-G30*Допущения!$B$27)+Допущения!$B$26 -> 42.5 | Q30: =P30/4.33 -> 9.8152425 | R30: =SUM(H14:H25) -> 8250000
A31: 30 | B31: =INT((A31-1)/12)+1 -> 3 | C31: =IF(A31<=3,1,IF(A31<=6,2,IF(A31<=12,3,IF(A31<=24,4,5)))) -> 5 | D31: =INDEX(Объёмы!$B$3:$F$3,C31) -> 2 | E31: =INDEX(Объёмы!$B$4:$F$4,C31) -> 0.75 | F31: =INDEX(Объёмы!$B$5:$F$5,C31) -> 3 | G31: =INDEX(Объёмы!$B$6:$F$6,C31) -> 1 | H31: =(D31*Допущения!$B$2+E31*Допущения!$B$3+F31*Допущения!$B$4)*IF(B31=1,1,IF(B31=2,Допущения!$B$8,Допущения!$B$9)) -> 1098000 | I31: =(D31*Допущения!$B$2*Допущения!$B$5+E31*Допущения!$B$3*Допущения!$B$6+F31*Допущения!$B$4*Допущения!$B$7)*IF(B31=1,1,IF(B31=2,Допущения!$B$8,Допущения!$B$9)) -> 377100 | J31: =H31-I31 -> 720900 | K31: =INDEX(Допущения!$B$10:$B$14, C31)+G31*Допущения!$B$15 -> 260000 | L31: =IF(R31>Допущения!$B$20,H31*Допущения!$B$21,0) -> 0 | M31: =(H31-L31)*Допущения!$B$16+MAX(0,H31-L31-Допущения!$B$18)*Допущения!$B$17+Допущения!$B$19 -> 81410 | N31: =J31-K31-L31-M31 -> 379490 | O31: =MAX(0,N31)*Допущения!$B$22 -> 265643 | P31: =MAX(0,D31*Допущения!$B$23+E31*Допущения!$B$24+F31*Допущения!$B$25-G31*Допущения!$B$27)+Допущения!$B$26 -> 42.5 | Q31: =P31/4.33 -> 9.8152425 | R31: =SUM(H14:H25) -> 8250000
A32: 31 | B32: =INT((A32-1)/12)+1 -> 3 | C32: =IF(A32<=3,1,IF(A32<=6,2,IF(A32<=12,3,IF(A32<=24,4,5)))) -> 5 | D32: =INDEX(Объёмы!$B$3:$F$3,C32) -> 2 | E32: =INDEX(Объёмы!$B$4:$F$4,C32) -> 0.75 | F32: =INDEX(Объёмы!$B$5:$F$5,C32) -> 3 | G32: =INDEX(Объёмы!$B$6:$F$6,C32) -> 1 | H32: =(D32*Допущения!$B$2+E32*Допущения!$B$3+F32*Допущения!$B$4)*IF(B32=1,1,IF(B32=2,Допущения!$B$8,Допущения!$B$9)) -> 1098000 | I32: =(D32*Допущения!$B$2*Допущения!$B$5+E32*Допущения!$B$3*Допущения!$B$6+F32*Допущения!$B$4*Допущения!$B$7)*IF(B32=1,1,IF(B32=2,Допущения!$B$8,Допущения!$B$9)) -> 377100 | J32: =H32-I32 -> 720900 | K32: =INDEX(Допущения!$B$10:$B$14, C32)+G32*Допущения!$B$15 -> 260000 | L32: =IF(R32>Допущения!$B$20,H32*Допущения!$B$21,0) -> 0 | M32: =(H32-L32)*Допущения!$B$16+MAX(0,H32-L32-Допущения!$B$18)*Допущения!$B$17+Допущения!$B$19 -> 81410 | N32: =J32-K32-L32-M32 -> 379490 | O32: =MAX(0,N32)*Допущения!$B$22 -> 265643 | P32: =MAX(0,D32*Допущения!$B$23+E32*Допущения!$B$24+F32*Допущения!$B$25-G32*Допущения!$B$27)+Допущения!$B$26 -> 42.5 | Q32: =P32/4.33 -> 9.8152425 | R32: =SUM(H14:H25) -> 8250000
A33: 32 | B33: =INT((A33-1)/12)+1 -> 3 | C33: =IF(A33<=3,1,IF(A33<=6,2,IF(A33<=12,3,IF(A33<=24,4,5)))) -> 5 | D33: =INDEX(Объёмы!$B$3:$F$3,C33) -> 2 | E33: =INDEX(Объёмы!$B$4:$F$4,C33) -> 0.75 | F33: =INDEX(Объёмы!$B$5:$F$5,C33) -> 3 | G33: =INDEX(Объёмы!$B$6:$F$6,C33) -> 1 | H33: =(D33*Допущения!$B$2+E33*Допущения!$B$3+F33*Допущения!$B$4)*IF(B33=1,1,IF(B33=2,Допущения!$B$8,Допущения!$B$9)) -> 1098000 | I33: =(D33*Допущения!$B$2*Допущения!$B$5+E33*Допущения!$B$3*Допущения!$B$6+F33*Допущения!$B$4*Допущения!$B$7)*IF(B33=1,1,IF(B33=2,Допущения!$B$8,Допущения!$B$9)) -> 377100 | J33: =H33-I33 -> 720900 | K33: =INDEX(Допущения!$B$10:$B$14, C33)+G33*Допущения!$B$15 -> 260000 | L33: =IF(R33>Допущения!$B$20,H33*Допущения!$B$21,0) -> 0 | M33: =(H33-L33)*Допущения!$B$16+MAX(0,H33-L33-Допущения!$B$18)*Допущения!$B$17+Допущения!$B$19 -> 81410 | N33: =J33-K33-L33-M33 -> 379490 | O33: =MAX(0,N33)*Допущения!$B$22 -> 265643 | P33: =MAX(0,D33*Допущения!$B$23+E33*Допущения!$B$24+F33*Допущения!$B$25-G33*Допущения!$B$27)+Допущения!$B$26 -> 42.5 | Q33: =P33/4.33 -> 9.8152425 | R33: =SUM(H14:H25) -> 8250000
A34: 33 | B34: =INT((A34-1)/12)+1 -> 3 | C34: =IF(A34<=3,1,IF(A34<=6,2,IF(A34<=12,3,IF(A34<=24,4,5)))) -> 5 | D34: =INDEX(Объёмы!$B$3:$F$3,C34) -> 2 | E34: =INDEX(Объёмы!$B$4:$F$4,C34) -> 0.75 | F34: =INDEX(Объёмы!$B$5:$F$5,C34) -> 3 | G34: =INDEX(Объёмы!$B$6:$F$6,C34) -> 1 | H34: =(D34*Допущения!$B$2+E34*Допущения!$B$3+F34*Допущения!$B$4)*IF(B34=1,1,IF(B34=2,Допущения!$B$8,Допущения!$B$9)) -> 1098000 | I34: =(D34*Допущения!$B$2*Допущения!$B$5+E34*Допущения!$B$3*Допущения!$B$6+F34*Допущения!$B$4*Допущения!$B$7)*IF(B34=1,1,IF(B34=2,Допущения!$B$8,Допущения!$B$9)) -> 377100 | J34: =H34-I34 -> 720900 | K34: =INDEX(Допущения!$B$10:$B$14, C34)+G34*Допущения!$B$15 -> 260000 | L34: =IF(R34>Допущения!$B$20,H34*Допущения!$B$21,0) -> 0 | M34: =(H34-L34)*Допущения!$B$16+MAX(0,H34-L34-Допущения!$B$18)*Допущения!$B$17+Допущения!$B$19 -> 81410 | N34: =J34-K34-L34-M34 -> 379490 | O34: =MAX(0,N34)*Допущения!$B$22 -> 265643 | P34: =MAX(0,D34*Допущения!$B$23+E34*Допущения!$B$24+F34*Допущения!$B$25-G34*Допущения!$B$27)+Допущения!$B$26 -> 42.5 | Q34: =P34/4.33 -> 9.8152425 | R34: =SUM(H14:H25) -> 8250000
A35: 34 | B35: =INT((A35-1)/12)+1 -> 3 | C35: =IF(A35<=3,1,IF(A35<=6,2,IF(A35<=12,3,IF(A35<=24,4,5)))) -> 5 | D35: =INDEX(Объёмы!$B$3:$F$3,C35) -> 2 | E35: =INDEX(Объёмы!$B$4:$F$4,C35) -> 0.75 | F35: =INDEX(Объёмы!$B$5:$F$5,C35) -> 3 | G35: =INDEX(Объёмы!$B$6:$F$6,C35) -> 1 | H35: =(D35*Допущения!$B$2+E35*Допущения!$B$3+F35*Допущения!$B$4)*IF(B35=1,1,IF(B35=2,Допущения!$B$8,Допущения!$B$9)) -> 1098000 | I35: =(D35*Допущения!$B$2*Допущения!$B$5+E35*Допущения!$B$3*Допущения!$B$6+F35*Допущения!$B$4*Допущения!$B$7)*IF(B35=1,1,IF(B35=2,Допущения!$B$8,Допущения!$B$9)) -> 377100 | J35: =H35-I35 -> 720900 | K35: =INDEX(Допущения!$B$10:$B$14, C35)+G35*Допущения!$B$15 -> 260000 | L35: =IF(R35>Допущения!$B$20,H35*Допущения!$B$21,0) -> 0 | M35: =(H35-L35)*Допущения!$B$16+MAX(0,H35-L35-Допущения!$B$18)*Допущения!$B$17+Допущения!$B$19 -> 81410 | N35: =J35-K35-L35-M35 -> 379490 | O35: =MAX(0,N35)*Допущения!$B$22 -> 265643 | P35: =MAX(0,D35*Допущения!$B$23+E35*Допущения!$B$24+F35*Допущения!$B$25-G35*Допущения!$B$27)+Допущения!$B$26 -> 42.5 | Q35: =P35/4.33 -> 9.8152425 | R35: =SUM(H14:H25) -> 8250000
A36: 35 | B36: =INT((A36-1)/12)+1 -> 3 | C36: =IF(A36<=3,1,IF(A36<=6,2,IF(A36<=12,3,IF(A36<=24,4,5)))) -> 5 | D36: =INDEX(Объёмы!$B$3:$F$3,C36) -> 2 | E36: =INDEX(Объёмы!$B$4:$F$4,C36) -> 0.75 | F36: =INDEX(Объёмы!$B$5:$F$5,C36) -> 3 | G36: =INDEX(Объёмы!$B$6:$F$6,C36) -> 1 | H36: =(D36*Допущения!$B$2+E36*Допущения!$B$3+F36*Допущения!$B$4)*IF(B36=1,1,IF(B36=2,Допущения!$B$8,Допущения!$B$9)) -> 1098000 | I36: =(D36*Допущения!$B$2*Допущения!$B$5+E36*Допущения!$B$3*Допущения!$B$6+F36*Допущения!$B$4*Допущения!$B$7)*IF(B36=1,1,IF(B36=2,Допущения!$B$8,Допущения!$B$9)) -> 377100 | J36: =H36-I36 -> 720900 | K36: =INDEX(Допущения!$B$10:$B$14, C36)+G36*Допущения!$B$15 -> 260000 | L36: =IF(R36>Допущения!$B$20,H36*Допущения!$B$21,0) -> 0 | M36: =(H36-L36)*Допущения!$B$16+MAX(0,H36-L36-Допущения!$B$18)*Допущения!$B$17+Допущения!$B$19 -> 81410 | N36: =J36-K36-L36-M36 -> 379490 | O36: =MAX(0,N36)*Допущения!$B$22 -> 265643 | P36: =MAX(0,D36*Допущения!$B$23+E36*Допущения!$B$24+F36*Допущения!$B$25-G36*Допущения!$B$27)+Допущения!$B$26 -> 42.5 | Q36: =P36/4.33 -> 9.8152425 | R36: =SUM(H14:H25) -> 8250000
A37: 36 | B37: =INT((A37-1)/12)+1 -> 3 | C37: =IF(A37<=3,1,IF(A37<=6,2,IF(A37<=12,3,IF(A37<=24,4,5)))) -> 5 | D37: =INDEX(Объёмы!$B$3:$F$3,C37) -> 2 | E37: =INDEX(Объёмы!$B$4:$F$4,C37) -> 0.75 | F37: =INDEX(Объёмы!$B$5:$F$5,C37) -> 3 | G37: =INDEX(Объёмы!$B$6:$F$6,C37) -> 1 | H37: =(D37*Допущения!$B$2+E37*Допущения!$B$3+F37*Допущения!$B$4)*IF(B37=1,1,IF(B37=2,Допущения!$B$8,Допущения!$B$9)) -> 1098000 | I37: =(D37*Допущения!$B$2*Допущения!$B$5+E37*Допущения!$B$3*Допущения!$B$6+F37*Допущения!$B$4*Допущения!$B$7)*IF(B37=1,1,IF(B37=2,Допущения!$B$8,Допущения!$B$9)) -> 377100 | J37: =H37-I37 -> 720900 | K37: =INDEX(Допущения!$B$10:$B$14, C37)+G37*Допущения!$B$15 -> 260000 | L37: =IF(R37>Допущения!$B$20,H37*Допущения!$B$21,0) -> 0 | M37: =(H37-L37)*Допущения!$B$16+MAX(0,H37-L37-Допущения!$B$18)*Допущения!$B$17+Допущения!$B$19 -> 81410 | N37: =J37-K37-L37-M37 -> 379490 | O37: =MAX(0,N37)*Допущения!$B$22 -> 265643 | P37: =MAX(0,D37*Допущения!$B$23+E37*Допущения!$B$24+F37*Допущения!$B$25-G37*Допущения!$B$27)+Допущения!$B$26 -> 42.5 | Q37: =P37/4.33 -> 9.8152425 | R37: =SUM(H14:H25) -> 8250000

Sheet Базовый
A1: Месяц | B1: Год | C1: Период | D1: Аудиты | E1: Core | F1: Абонементы | G1: FTE | H1: Выручка | I1: Себестоимость | J1: Валовая прибыль | K1: Opex (вкл. FTE) | L1: НДС | M1: УСН+взносы | N1: Прибыль после налогов | O1: Изъятие основателя | P1: Часы основателя/мес | Q1: Часы основателя/нед | R1: Выручка за год до
A2: 1 | B2: =INT((A2-1)/12)+1 -> 1 | C2: =IF(A2<=3,1,IF(A2<=6,2,IF(A2<=12,3,IF(A2<=24,4,5)))) -> 1 | D2: =INDEX(Объёмы!$B$8:$F$8,C2) -> 0.67 | E2: =INDEX(Объёмы!$B$9:$F$9,C2) -> 0 | F2: =INDEX(Объёмы!$B$10:$F$10,C2) -> 0 | G2: =INDEX(Объёмы!$B$11:$F$11,C2) -> 0 | H2: =(D2*Допущения!$B$2+E2*Допущения!$B$3+F2*Допущения!$B$4)*IF(B2=1,1,IF(B2=2,Допущения!$B$8,Допущения!$B$9)) -> 60300 | I2: =(D2*Допущения!$B$2*Допущения!$B$5+E2*Допущения!$B$3*Допущения!$B$6+F2*Допущения!$B$4*Допущения!$B$7)*IF(B2=1,1,IF(B2=2,Допущения!$B$8,Допущения!$B$9)) -> 12060 | J2: =H2-I2 -> 48240 | K2: =INDEX(Допущения!$B$10:$B$14, C2)+G2*Допущения!$B$15 -> 35000 | L2: =IF(R2>Допущения!$B$20,H2*Допущения!$B$21,0) -> 0 | M2: =(H2-L2)*Допущения!$B$16+MAX(0,H2-L2-Допущения!$B$18)*Допущения!$B$17+Допущения!$B$19 -> 8771 | N2: =J2-K2-L2-M2 -> 4469 | O2: =MAX(0,N2)*Допущения!$B$22 -> 3128.3 | P2: =MAX(0,D2*Допущения!$B$23+E2*Допущения!$B$24+F2*Допущения!$B$25-G2*Допущения!$B$27)+Допущения!$B$26 -> 22.7 | Q2: =P2/4.33 -> 5.2424942 | R2: 0
A3: 2 | B3: =INT((A3-1)/12)+1 -> 1 | C3: =IF(A3<=3,1,IF(A3<=6,2,IF(A3<=12,3,IF(A3<=24,4,5)))) -> 1 | D3: =INDEX(Объёмы!$B$8:$F$8,C3) -> 0.67 | E3: =INDEX(Объёмы!$B$9:$F$9,C3) -> 0 | F3: =INDEX(Объёмы!$B$10:$F$10,C3) -> 0 | G3: =INDEX(Объёмы!$B$11:$F$11,C3) -> 0 | H3: =(D3*Допущения!$B$2+E3*Допущения!$B$3+F3*Допущения!$B$4)*IF(B3=1,1,IF(B3=2,Допущения!$B$8,Допущения!$B$9)) -> 60300 | I3: =(D3*Допущения!$B$2*Допущения!$B$5+E3*Допущения!$B$3*Допущения!$B$6+F3*Допущения!$B$4*Допущения!$B$7)*IF(B3=1,1,IF(B3=2,Допущения!$B$8,Допущения!$B$9)) -> 12060 | J3: =H3-I3 -> 48240 | K3: =INDEX(Допущения!$B$10:$B$14, C3)+G3*Допущения!$B$15 -> 35000 | L3: =IF(R3>Допущения!$B$20,H3*Допущения!$B$21,0) -> 0 | M3: =(H3-L3)*Допущения!$B$16+MAX(0,H3-L3-Допущения!$B$18)*Допущения!$B$17+Допущения!$B$19 -> 8771 | N3: =J3-K3-L3-M3 -> 4469 | O3: =MAX(0,N3)*Допущения!$B$22 -> 3128.3 | P3: =MAX(0,D3*Допущения!$B$23+E3*Допущения!$B$24+F3*Допущения!$B$25-G3*Допущения!$B$27)+Допущения!$B$26 -> 22.7 | Q3: =P3/4.33 -> 5.2424942 | R3: 0
A4: 3 | B4: =INT((A4-1)/12)+1 -> 1 | C4: =IF(A4<=3,1,IF(A4<=6,2,IF(A4<=12,3,IF(A4<=24,4,5)))) -> 1 | D4: =INDEX(Объёмы!$B$8:$F$8,C4) -> 0.67 | E4: =INDEX(Объёмы!$B$9:$F$9,C4) -> 0 | F4: =INDEX(Объёмы!$B$10:$F$10,C4) -> 0 | G4: =INDEX(Объёмы!$B$11:$F$11,C4) -> 0 | H4: =(D4*Допущения!$B$2+E4*Допущения!$B$3+F4*Допущения!$B$4)*IF(B4=1,1,IF(B4=2,Допущения!$B$8,Допущения!$B$9)) -> 60300 | I4: =(D4*Допущения!$B$2*Допущения!$B$5+E4*Допущения!$B$3*Допущения!$B$6+F4*Допущения!$B$4*Допущения!$B$7)*IF(B4=1,1,IF(B4=2,Допущения!$B$8,Допущения!$B$9)) -> 12060 | J4: =H4-I4 -> 48240 | K4: =INDEX(Допущения!$B$10:$B$14, C4)+G4*Допущения!$B$15 -> 35000 | L4: =IF(R4>Допущения!$B$20,H4*Допущения!$B$21,0) -> 0 | M4: =(H4-L4)*Допущения!$B$16+MAX(0,H4-L4-Допущения!$B$18)*Допущения!$B$17+Допущения!$B$19 -> 8771 | N4: =J4-K4-L4-M4 -> 4469 | O4: =MAX(0,N4)*Допущения!$B$22 -> 3128.3 | P4: =MAX(0,D4*Допущения!$B$23+E4*Допущения!$B$24+F4*Допущения!$B$25-G4*Допущения!$B$27)+Допущения!$B$26 -> 22.7 | Q4: =P4/4.33 -> 5.2424942 | R4: 0
A5: 4 | B5: =INT((A5-1)/12)+1 -> 1 | C5: =IF(A5<=3,1,IF(A5<=6,2,IF(A5<=12,3,IF(A5<=24,4,5)))) -> 2 | D5: =INDEX(Объёмы!$B$8:$F$8,C5) -> 1 | E5: =INDEX(Объёмы!$B$9:$F$9,C5) -> 0.5 | F5: =INDEX(Объёмы!$B$10:$F$10,C5) -> 1 | G5: =INDEX(Объёмы!$B$11:$F$11,C5) -> 0 | H5: =(D5*Допущения!$B$2+E5*Допущения!$B$3+F5*Допущения!$B$4)*IF(B5=1,1,IF(B5=2,Допущения!$B$8,Допущения!$B$9)) -> 440000 | I5: =(D5*Допущения!$B$2*Допущения!$B$5+E5*Допущения!$B$3*Допущения!$B$6+F5*Допущения!$B$4*Допущения!$B$7)*IF(B5=1,1,IF(B5=2,Допущения!$B$8,Допущения!$B$9)) -> 147500 | J5: =H5-I5 -> 292500 | K5: =INDEX(Допущения!$B$10:$B$14, C5)+G5*Допущения!$B$15 -> 35000 | L5: =IF(R5>Допущения!$B$20,H5*Допущения!$B$21,0) -> 0 | M5: =(H5-L5)*Допущения!$B$16+MAX(0,H5-L5-Допущения!$B$18)*Допущения!$B$17+Допущения!$B$19 -> 35350 | N5: =J5-K5-L5-M5 -> 222150 | O5: =MAX(0,N5)*Допущения!$B$22 -> 155505 | P5: =MAX(0,D5*Допущения!$B$23+E5*Допущения!$B$24+F5*Допущения!$B$25-G5*Допущения!$B$27)+Допущения!$B$26 -> 49 | Q5: =P5/4.33 -> 11.316397 | R5: 0
A6: 5 | B6: =INT((A6-1)/12)+1 -> 1 | C6: =IF(A6<=3,1,IF(A6<=6,2,IF(A6<=12,3,IF(A6<=24,4,5)))) -> 2 | D6: =INDEX(Объёмы!$B$8:$F$8,C6) -> 1 | E6: =INDEX(Объёмы!$B$9:$F$9,C6) -> 0.5 | F6: =INDEX(Объёмы!$B$10:$F$10,C6) -> 1 | G6: =INDEX(Объёмы!$B$11:$F$11,C6) -> 0 | H6: =(D6*Допущения!$B$2+E6*Допущения!$B$3+F6*Допущения!$B$4)*IF(B6=1,1,IF(B6=2,Допущения!$B$8,Допущения!$B$9)) -> 440000 | I6: =(D6*Допущения!$B$2*Допущения!$B$5+E6*Допущения!$B$3*Допущения!$B$6+F6*Допущения!$B$4*Допущения!$B$7)*IF(B6=1,1,IF(B6=2,Допущения!$B$8,Допущения!$B$9)) -> 147500 | J6: =H6-I6 -> 292500 | K6: =INDEX(Допущения!$B$10:$B$14, C6)+G6*Допущения!$B$15 -> 35000 | L6: =IF(R6>Допущения!$B$20,H6*Допущения!$B$21,0) -> 0 | M6: =(H6-L6)*Допущения!$B$16+MAX(0,H6-L6-Допущения!$B$18)*Допущения!$B$17+Допущения!$B$19 -> 35350 | N6: =J6-K6-L6-M6 -> 222150 | O6: =MAX(0,N6)*Допущения!$B$22 -> 155505 | P6: =MAX(0,D6*Допущения!$B$23+E6*Допущения!$B$24+F6*Допущения!$B$25-G6*Допущения!$B$27)+Допущения!$B$26 -> 49 | Q6: =P6/4.33 -> 11.316397 | R6: 0
A7: 6 | B7: =INT((A7-1)/12)+1 -> 1 | C7: =IF(A7<=3,1,IF(A7<=6,2,IF(A7<=12,3,IF(A7<=24,4,5)))) -> 2 | D7: =INDEX(Объёмы!$B$8:$F$8,C7) -> 1 | E7: =INDEX(Объёмы!$B$9:$F$9,C7) -> 0.5 | F7: =INDEX(Объёмы!$B$10:$F$10,C7) -> 1 | G7: =INDEX(Объёмы!$B$11:$F$11,C7) -> 0 | H7: =(D7*Допущения!$B$2+E7*Допущения!$B$3+F7*Допущения!$B$4)*IF(B7=1,1,IF(B7=2,Допущения!$B$8,Допущения!$B$9)) -> 440000 | I7: =(D7*Допущения!$B$2*Допущения!$B$5+E7*Допущения!$B$3*Допущения!$B$6+F7*Допущения!$B$4*Допущения!$B$7)*IF(B7=1,1,IF(B7=2,Допущения!$B$8,Допущения!$B$9)) -> 147500 | J7: =H7-I7 -> 292500 | K7: =INDEX(Допущения!$B$10:$B$14, C7)+G7*Допущения!$B$15 -> 35000 | L7: =IF(R7>Допущения!$B$20,H7*Допущения!$B$21,0) -> 0 | M7: =(H7-L7)*Допущения!$B$16+MAX(0,H7-L7-Допущения!$B$18)*Допущения!$B$17+Допущения!$B$19 -> 35350 | N7: =J7-K7-L7-M7 -> 222150 | O7: =MAX(0,N7)*Допущения!$B$22 -> 155505 | P7: =MAX(0,D7*Допущения!$B$23+E7*Допущения!$B$24+F7*Допущения!$B$25-G7*Допущения!$B$27)+Допущения!$B$26 -> 49 | Q7: =P7/4.33 -> 11.316397 | R7: 0
A8: 7 | B8: =INT((A8-1)/12)+1 -> 1 | C8: =IF(A8<=3,1,IF(A8<=6,2,IF(A8<=12,3,IF(A8<=24,4,5)))) -> 3 | D8: =INDEX(Объёмы!$B$8:$F$8,C8) -> 1 | E8: =INDEX(Объёмы!$B$9:$F$9,C8) -> 0.5 | F8: =INDEX(Объёмы!$B$10:$F$10,C8) -> 2 | G8: =INDEX(Объёмы!$B$11:$F$11,C8) -> 0 | H8: =(D8*Допущения!$B$2+E8*Допущения!$B$3+F8*Допущения!$B$4)*IF(B8=1,1,IF(B8=2,Допущения!$B$8,Допущения!$B$9)) -> 580000 | I8: =(D8*Допущения!$B$2*Допущения!$B$5+E8*Допущения!$B$3*Допущения!$B$6+F8*Допущения!$B$4*Допущения!$B$7)*IF(B8=1,1,IF(B8=2,Допущения!$B$8,Допущения!$B$9)) -> 203500 | J8: =H8-I8 -> 376500 | K8: =INDEX(Допущения!$B$10:$B$14, C8)+G8*Допущения!$B$15 -> 45000 | L8: =IF(R8>Допущения!$B$20,H8*Допущения!$B$21,0) -> 0 | M8: =(H8-L8)*Допущения!$B$16+MAX(0,H8-L8-Допущения!$B$18)*Допущения!$B$17+Допущения!$B$19 -> 45150 | N8: =J8-K8-L8-M8 -> 286350 | O8: =MAX(0,N8)*Допущения!$B$22 -> 200445 | P8: =MAX(0,D8*Допущения!$B$23+E8*Допущения!$B$24+F8*Допущения!$B$25-G8*Допущения!$B$27)+Допущения!$B$26 -> 57 | Q8: =P8/4.33 -> 13.163972 | R8: 0
A9: 8 | B9: =INT((A9-1)/12)+1 -> 1 | C9: =IF(A9<=3,1,IF(A9<=6,2,IF(A9<=12,3,IF(A9<=24,4,5)))) -> 3 | D9: =INDEX(Объёмы!$B$8:$F$8,C9) -> 1 | E9: =INDEX(Объёмы!$B$9:$F$9,C9) -> 0.5 | F9: =INDEX(Объёмы!$B$10:$F$10,C9) -> 2 | G9: =INDEX(Объёмы!$B$11:$F$11,C9) -> 0 | H9: =(D9*Допущения!$B$2+E9*Допущения!$B$3+F9*Допущения!$B$4)*IF(B9=1,1,IF(B9=2,Допущения!$B$8,Допущения!$B$9)) -> 580000 | I9: =(D9*Допущения!$B$2*Допущения!$B$5+E9*Допущения!$B$3*Допущения!$B$6+F9*Допущения!$B$4*Допущения!$B$7)*IF(B9=1,1,IF(B9=2,Допущения!$B$8,Допущения!$B$9)) -> 203500 | J9: =H9-I9 -> 376500 | K9: =INDEX(Допущения!$B$10:$B$14, C9)+G9*Допущения!$B$15 -> 45000 | L9: =IF(R9>Допущения!$B$20,H9*Допущения!$B$21,0) -> 0 | M9: =(H9-L9)*Допущения!$B$16+MAX(0,H9-L9-Допущения!$B$18)*Допущения!$B$17+Допущения!$B$19 -> 45150 | N9: =J9-K9-L9-M9 -> 286350 | O9: =MAX(0,N9)*Допущения!$B$22 -> 200445 | P9: =MAX(0,D9*Допущения!$B$23+E9*Допущения!$B$24+F9*Допущения!$B$25-G9*Допущения!$B$27)+Допущения!$B$26 -> 57 | Q9: =P9/4.33 -> 13.163972 | R9: 0
A10: 9 | B10: =INT((A10-1)/12)+1 -> 1 | C10: =IF(A10<=3,1,IF(A10<=6,2,IF(A10<=12,3,IF(A10<=24,4,5)))) -> 3 | D10: =INDEX(Объёмы!$B$8:$F$8,C10) -> 1 | E10: =INDEX(Объёмы!$B$9:$F$9,C10) -> 0.5 | F10: =INDEX(Объёмы!$B$10:$F$10,C10) -> 2 | G10: =INDEX(Объёмы!$B$11:$F$11,C10) -> 0 | H10: =(D10*Допущения!$B$2+E10*Допущения!$B$3+F10*Допущения!$B$4)*IF(B10=1,1,IF(B10=2,Допущения!$B$8,Допущения!$B$9)) -> 580000 | I10: =(D10*Допущения!$B$2*Допущения!$B$5+E10*Допущения!$B$3*Допущения!$B$6+F10*Допущения!$B$4*Допущения!$B$7)*IF(B10=1,1,IF(B10=2,Допущения!$B$8,Допущения!$B$9)) -> 203500 | J10: =H10-I10 -> 376500 | K10: =INDEX(Допущения!$B$10:$B$14, C10)+G10*Допущения!$B$15 -> 45000 | L10: =IF(R10>Допущения!$B$20,H10*Допущения!$B$21,0) -> 0 | M10: =(H10-L10)*Допущения!$B$16+MAX(0,H10-L10-Допущения!$B$18)*Допущения!$B$17+Допущения!$B$19 -> 45150 | N10: =J10-K10-L10-M10 -> 286350 | O10: =MAX(0,N10)*Допущения!$B$22 -> 200445 | P10: =MAX(0,D10*Допущения!$B$23+E10*Допущения!$B$24+F10*Допущения!$B$25-G10*Допущения!$B$27)+Допущения!$B$26 -> 57 | Q10: =P10/4.33 -> 13.163972 | R10: 0
A11: 10 | B11: =INT((A11-1)/12)+1 -> 1 | C11: =IF(A11<=3,1,IF(A11<=6,2,IF(A11<=12,3,IF(A11<=24,4,5)))) -> 3 | D11: =INDEX(Объёмы!$B$8:$F$8,C11) -> 1 | E11: =INDEX(Объёмы!$B$9:$F$9,C11) -> 0.5 | F11: =INDEX(Объёмы!$B$10:$F$10,C11) -> 2 | G11: =INDEX(Объёмы!$B$11:$F$11,C11) -> 0 | H11: =(D11*Допущения!$B$2+E11*Допущения!$B$3+F11*Допущения!$B$4)*IF(B11=1,1,IF(B11=2,Допущения!$B$8,Допущения!$B$9)) -> 580000 | I11: =(D11*Допущения!$B$2*Допущения!$B$5+E11*Допущения!$B$3*Допущения!$B$6+F11*Допущения!$B$4*Допущения!$B$7)*IF(B11=1,1,IF(B11=2,Допущения!$B$8,Допущения!$B$9)) -> 203500 | J11: =H11-I11 -> 376500 | K11: =INDEX(Допущения!$B$10:$B$14, C11)+G11*Допущения!$B$15 -> 45000 | L11: =IF(R11>Допущения!$B$20,H11*Допущения!$B$21,0) -> 0 | M11: =(H11-L11)*Допущения!$B$16+MAX(0,H11-L11-Допущения!$B$18)*Допущения!$B$17+Допущения!$B$19 -> 45150 | N11: =J11-K11-L11-M11 -> 286350 | O11: =MAX(0,N11)*Допущения!$B$22 -> 200445 | P11: =MAX(0,D11*Допущения!$B$23+E11*Допущения!$B$24+F11*Допущения!$B$25-G11*Допущения!$B$27)+Допущения!$B$26 -> 57 | Q11: =P11/4.33 -> 13.163972 | R11: 0
